INFO:root:Fetching data from API...
Traceback (most recent call last):
  File "/usr/lib/python3/dist-packages/urllib3/connection.py", line 159, in _new_conn
    conn = connection.create_connection(
  File "/usr/lib/python3/dist-packages/urllib3/util/connection.py", line 84, in create_connection
    raise err
  File "/usr/lib/python3/dist-packages/urllib3/util/connection.py", line 74, in create_connection
    sock.connect(sa)
ConnectionRefusedError: [Errno 111] Connection refused

During handling of the above exception, another exception occurred:

Traceback (most recent call last):
  File "/usr/lib/python3/dist-packages/urllib3/connectionpool.py", line 665, in urlopen
    httplib_response = self._make_request(
  File "/usr/lib/python3/dist-packages/urllib3/connectionpool.py", line 387, in _make_request
    conn.request(method, url, **httplib_request_kw)
  File "/usr/lib/python3.8/http/client.py", line 1256, in request
    self._send_request(method, url, body, headers, encode_chunked)
  File "/usr/lib/python3.8/http/client.py", line 1302, in _send_request
    self.endheaders(body, encode_chunked=encode_chunked)
  File "/usr/lib/python3.8/http/client.py", line 1251, in endheaders
    self._send_output(message_body, encode_chunked=encode_chunked)
  File "/usr/lib/python3.8/http/client.py", line 1011, in _send_output
    self.send(msg)
  File "/usr/lib/python3.8/http/client.py", line 951, in send
    self.connect()
  File "/usr/lib/python3/dist-packages/urllib3/connection.py", line 187, in connect
    conn = self._new_conn()
  File "/usr/lib/python3/dist-packages/urllib3/connection.py", line 171, in _new_conn
    raise NewConnectionError(
urllib3.exceptions.NewConnectionError: <urllib3.connection.HTTPConnection object at 0x79069e132190>: Failed to establish a new connection: [Errno 111] Connection refused

During handling of the above exception, another exception occurred:

Traceback (most recent call last):
  File "/usr/lib/python3/dist-packages/requests/adapters.py", line 439, in send
    resp = conn.urlopen(
  File "/usr/lib/python3/dist-packages/urllib3/connectionpool.py", line 719, in urlopen
    retries = retries.increment(
  File "/usr/lib/python3/dist-packages/urllib3/util/retry.py", line 436, in increment
    raise MaxRetryError(_pool, url, error or ResponseError(cause))
urllib3.exceptions.MaxRetryError: HTTPConnectionPool(host='localhost', port=8000): Max retries exceeded with url: /users.json (Caused by NewConnectionError('<urllib3.connection.HTTPConnection object at 0x79069e132190>: Failed to establish a new connection: [Errno 111] Connection refused'))

During handling of the above exception, another exception occurred:

Traceback (most recent call last):
  File "/mnt/c/Users/manib/data_pipeline_project/pipeline.py", line 39, in <module>
    run_pipeline()
  File "/mnt/c/Users/manib/data_pipeline_project/pipeline.py", line 35, in run_pipeline
    data = fetch_data()
  File "/mnt/c/Users/manib/data_pipeline_project/pipeline.py", line 10, in fetch_data
    response = requests.get("http://localhost:8000/users.json")
  File "/usr/lib/python3/dist-packages/requests/api.py", line 75, in get
    return request('get', url, params=params, **kwargs)
  File "/usr/lib/python3/dist-packages/requests/api.py", line 60, in request
    return session.request(method=method, url=url, **kwargs)
  File "/usr/lib/python3/dist-packages/requests/sessions.py", line 533, in request
    resp = self.send(prep, **send_kwargs)
  File "/usr/lib/python3/dist-packages/requests/sessions.py", line 646, in send
    r = adapter.send(request, **kwargs)
  File "/usr/lib/python3/dist-packages/requests/adapters.py", line 516, in send
    raise ConnectionError(e, request=request)
requests.exceptions.ConnectionError: HTTPConnectionPool(host='localhost', port=8000): Max retries exceeded with url: /users.json (Caused by NewConnectionError('<urllib3.connection.HTTPConnection object at 0x79069e132190>: Failed to establish a new connection: [Errno 111] Connection refused'))
INFO:root:Fetching data from API...
Traceback (most recent call last):
  File "/usr/lib/python3/dist-packages/urllib3/connection.py", line 159, in _new_conn
    conn = connection.create_connection(
  File "/usr/lib/python3/dist-packages/urllib3/util/connection.py", line 84, in create_connection
    raise err
  File "/usr/lib/python3/dist-packages/urllib3/util/connection.py", line 74, in create_connection
    sock.connect(sa)
ConnectionRefusedError: [Errno 111] Connection refused

During handling of the above exception, another exception occurred:

Traceback (most recent call last):
  File "/usr/lib/python3/dist-packages/urllib3/connectionpool.py", line 665, in urlopen
    httplib_response = self._make_request(
  File "/usr/lib/python3/dist-packages/urllib3/connectionpool.py", line 387, in _make_request
    conn.request(method, url, **httplib_request_kw)
  File "/usr/lib/python3.8/http/client.py", line 1256, in request
    self._send_request(method, url, body, headers, encode_chunked)
  File "/usr/lib/python3.8/http/client.py", line 1302, in _send_request
    self.endheaders(body, encode_chunked=encode_chunked)
  File "/usr/lib/python3.8/http/client.py", line 1251, in endheaders
    self._send_output(message_body, encode_chunked=encode_chunked)
  File "/usr/lib/python3.8/http/client.py", line 1011, in _send_output
    self.send(msg)
  File "/usr/lib/python3.8/http/client.py", line 951, in send
    self.connect()
  File "/usr/lib/python3/dist-packages/urllib3/connection.py", line 187, in connect
    conn = self._new_conn()
  File "/usr/lib/python3/dist-packages/urllib3/connection.py", line 171, in _new_conn
    raise NewConnectionError(
urllib3.exceptions.NewConnectionError: <urllib3.connection.HTTPConnection object at 0x7dbb711116a0>: Failed to establish a new connection: [Errno 111] Connection refused

During handling of the above exception, another exception occurred:

Traceback (most recent call last):
  File "/usr/lib/python3/dist-packages/requests/adapters.py", line 439, in send
    resp = conn.urlopen(
  File "/usr/lib/python3/dist-packages/urllib3/connectionpool.py", line 719, in urlopen
    retries = retries.increment(
  File "/usr/lib/python3/dist-packages/urllib3/util/retry.py", line 436, in increment
    raise MaxRetryError(_pool, url, error or ResponseError(cause))
urllib3.exceptions.MaxRetryError: HTTPConnectionPool(host='localhost', port=8000): Max retries exceeded with url: /users.json (Caused by NewConnectionError('<urllib3.connection.HTTPConnection object at 0x7dbb711116a0>: Failed to establish a new connection: [Errno 111] Connection refused'))

During handling of the above exception, another exception occurred:

Traceback (most recent call last):
  File "/mnt/c/Users/manib/data_pipeline_project/pipeline.py", line 39, in <module>
    run_pipeline()
  File "/mnt/c/Users/manib/data_pipeline_project/pipeline.py", line 35, in run_pipeline
    data = fetch_data()
  File "/mnt/c/Users/manib/data_pipeline_project/pipeline.py", line 10, in fetch_data
    response = requests.get("http://localhost:8000/users.json")
  File "/usr/lib/python3/dist-packages/requests/api.py", line 75, in get
    return request('get', url, params=params, **kwargs)
  File "/usr/lib/python3/dist-packages/requests/api.py", line 60, in request
    return session.request(method=method, url=url, **kwargs)
  File "/usr/lib/python3/dist-packages/requests/sessions.py", line 533, in request
    resp = self.send(prep, **send_kwargs)
  File "/usr/lib/python3/dist-packages/requests/sessions.py", line 646, in send
    r = adapter.send(request, **kwargs)
  File "/usr/lib/python3/dist-packages/requests/adapters.py", line 516, in send
    raise ConnectionError(e, request=request)
requests.exceptions.ConnectionError: HTTPConnectionPool(host='localhost', port=8000): Max retries exceeded with url: /users.json (Caused by NewConnectionError('<urllib3.connection.HTTPConnection object at 0x7dbb711116a0>: Failed to establish a new connection: [Errno 111] Connection refused'))
INFO:root:Fetching data from API...
Traceback (most recent call last):
  File "/usr/lib/python3/dist-packages/urllib3/connection.py", line 159, in _new_conn
    conn = connection.create_connection(
  File "/usr/lib/python3/dist-packages/urllib3/util/connection.py", line 84, in create_connection
    raise err
  File "/usr/lib/python3/dist-packages/urllib3/util/connection.py", line 74, in create_connection
    sock.connect(sa)
ConnectionRefusedError: [Errno 111] Connection refused

During handling of the above exception, another exception occurred:

Traceback (most recent call last):
  File "/usr/lib/python3/dist-packages/urllib3/connectionpool.py", line 665, in urlopen
    httplib_response = self._make_request(
  File "/usr/lib/python3/dist-packages/urllib3/connectionpool.py", line 387, in _make_request
    conn.request(method, url, **httplib_request_kw)
  File "/usr/lib/python3.8/http/client.py", line 1256, in request
    self._send_request(method, url, body, headers, encode_chunked)
  File "/usr/lib/python3.8/http/client.py", line 1302, in _send_request
    self.endheaders(body, encode_chunked=encode_chunked)
  File "/usr/lib/python3.8/http/client.py", line 1251, in endheaders
    self._send_output(message_body, encode_chunked=encode_chunked)
  File "/usr/lib/python3.8/http/client.py", line 1011, in _send_output
    self.send(msg)
  File "/usr/lib/python3.8/http/client.py", line 951, in send
    self.connect()
  File "/usr/lib/python3/dist-packages/urllib3/connection.py", line 187, in connect
    conn = self._new_conn()
  File "/usr/lib/python3/dist-packages/urllib3/connection.py", line 171, in _new_conn
    raise NewConnectionError(
urllib3.exceptions.NewConnectionError: <urllib3.connection.HTTPConnection object at 0x723649f72190>: Failed to establish a new connection: [Errno 111] Connection refused

During handling of the above exception, another exception occurred:

Traceback (most recent call last):
  File "/usr/lib/python3/dist-packages/requests/adapters.py", line 439, in send
    resp = conn.urlopen(
  File "/usr/lib/python3/dist-packages/urllib3/connectionpool.py", line 719, in urlopen
    retries = retries.increment(
  File "/usr/lib/python3/dist-packages/urllib3/util/retry.py", line 436, in increment
    raise MaxRetryError(_pool, url, error or ResponseError(cause))
urllib3.exceptions.MaxRetryError: HTTPConnectionPool(host='localhost', port=8000): Max retries exceeded with url: /users.json (Caused by NewConnectionError('<urllib3.connection.HTTPConnection object at 0x723649f72190>: Failed to establish a new connection: [Errno 111] Connection refused'))

During handling of the above exception, another exception occurred:

Traceback (most recent call last):
  File "/mnt/c/Users/manib/data_pipeline_project/pipeline.py", line 39, in <module>
    run_pipeline()
  File "/mnt/c/Users/manib/data_pipeline_project/pipeline.py", line 35, in run_pipeline
    data = fetch_data()
  File "/mnt/c/Users/manib/data_pipeline_project/pipeline.py", line 10, in fetch_data
    response = requests.get("http://localhost:8000/users.json")
  File "/usr/lib/python3/dist-packages/requests/api.py", line 75, in get
    return request('get', url, params=params, **kwargs)
  File "/usr/lib/python3/dist-packages/requests/api.py", line 60, in request
    return session.request(method=method, url=url, **kwargs)
  File "/usr/lib/python3/dist-packages/requests/sessions.py", line 533, in request
    resp = self.send(prep, **send_kwargs)
  File "/usr/lib/python3/dist-packages/requests/sessions.py", line 646, in send
    r = adapter.send(request, **kwargs)
  File "/usr/lib/python3/dist-packages/requests/adapters.py", line 516, in send
    raise ConnectionError(e, request=request)
requests.exceptions.ConnectionError: HTTPConnectionPool(host='localhost', port=8000): Max retries exceeded with url: /users.json (Caused by NewConnectionError('<urllib3.connection.HTTPConnection object at 0x723649f72190>: Failed to establish a new connection: [Errno 111] Connection refused'))
INFO:root:Fetching data from API...
Traceback (most recent call last):
  File "/usr/lib/python3/dist-packages/urllib3/connection.py", line 159, in _new_conn
    conn = connection.create_connection(
  File "/usr/lib/python3/dist-packages/urllib3/util/connection.py", line 84, in create_connection
    raise err
  File "/usr/lib/python3/dist-packages/urllib3/util/connection.py", line 74, in create_connection
    sock.connect(sa)
ConnectionRefusedError: [Errno 111] Connection refused

During handling of the above exception, another exception occurred:

Traceback (most recent call last):
  File "/usr/lib/python3/dist-packages/urllib3/connectionpool.py", line 665, in urlopen
    httplib_response = self._make_request(
  File "/usr/lib/python3/dist-packages/urllib3/connectionpool.py", line 387, in _make_request
    conn.request(method, url, **httplib_request_kw)
  File "/usr/lib/python3.8/http/client.py", line 1256, in request
    self._send_request(method, url, body, headers, encode_chunked)
  File "/usr/lib/python3.8/http/client.py", line 1302, in _send_request
    self.endheaders(body, encode_chunked=encode_chunked)
  File "/usr/lib/python3.8/http/client.py", line 1251, in endheaders
    self._send_output(message_body, encode_chunked=encode_chunked)
  File "/usr/lib/python3.8/http/client.py", line 1011, in _send_output
    self.send(msg)
  File "/usr/lib/python3.8/http/client.py", line 951, in send
    self.connect()
  File "/usr/lib/python3/dist-packages/urllib3/connection.py", line 187, in connect
    conn = self._new_conn()
  File "/usr/lib/python3/dist-packages/urllib3/connection.py", line 171, in _new_conn
    raise NewConnectionError(
urllib3.exceptions.NewConnectionError: <urllib3.connection.HTTPConnection object at 0x7b1ed7313190>: Failed to establish a new connection: [Errno 111] Connection refused

During handling of the above exception, another exception occurred:

Traceback (most recent call last):
  File "/usr/lib/python3/dist-packages/requests/adapters.py", line 439, in send
    resp = conn.urlopen(
  File "/usr/lib/python3/dist-packages/urllib3/connectionpool.py", line 719, in urlopen
    retries = retries.increment(
  File "/usr/lib/python3/dist-packages/urllib3/util/retry.py", line 436, in increment
    raise MaxRetryError(_pool, url, error or ResponseError(cause))
urllib3.exceptions.MaxRetryError: HTTPConnectionPool(host='localhost', port=8000): Max retries exceeded with url: /users.json (Caused by NewConnectionError('<urllib3.connection.HTTPConnection object at 0x7b1ed7313190>: Failed to establish a new connection: [Errno 111] Connection refused'))

During handling of the above exception, another exception occurred:

Traceback (most recent call last):
  File "/mnt/c/Users/manib/data_pipeline_project/pipeline.py", line 39, in <module>
    run_pipeline()
  File "/mnt/c/Users/manib/data_pipeline_project/pipeline.py", line 35, in run_pipeline
    data = fetch_data()
  File "/mnt/c/Users/manib/data_pipeline_project/pipeline.py", line 10, in fetch_data
    response = requests.get("http://localhost:8000/users.json")
  File "/usr/lib/python3/dist-packages/requests/api.py", line 75, in get
    return request('get', url, params=params, **kwargs)
  File "/usr/lib/python3/dist-packages/requests/api.py", line 60, in request
    return session.request(method=method, url=url, **kwargs)
  File "/usr/lib/python3/dist-packages/requests/sessions.py", line 533, in request
    resp = self.send(prep, **send_kwargs)
  File "/usr/lib/python3/dist-packages/requests/sessions.py", line 646, in send
    r = adapter.send(request, **kwargs)
  File "/usr/lib/python3/dist-packages/requests/adapters.py", line 516, in send
    raise ConnectionError(e, request=request)
requests.exceptions.ConnectionError: HTTPConnectionPool(host='localhost', port=8000): Max retries exceeded with url: /users.json (Caused by NewConnectionError('<urllib3.connection.HTTPConnection object at 0x7b1ed7313190>: Failed to establish a new connection: [Errno 111] Connection refused'))
INFO:root:Fetching data from API...
Traceback (most recent call last):
  File "/usr/lib/python3/dist-packages/urllib3/connection.py", line 159, in _new_conn
    conn = connection.create_connection(
  File "/usr/lib/python3/dist-packages/urllib3/util/connection.py", line 84, in create_connection
    raise err
  File "/usr/lib/python3/dist-packages/urllib3/util/connection.py", line 74, in create_connection
    sock.connect(sa)
ConnectionRefusedError: [Errno 111] Connection refused

During handling of the above exception, another exception occurred:

Traceback (most recent call last):
  File "/usr/lib/python3/dist-packages/urllib3/connectionpool.py", line 665, in urlopen
    httplib_response = self._make_request(
  File "/usr/lib/python3/dist-packages/urllib3/connectionpool.py", line 387, in _make_request
    conn.request(method, url, **httplib_request_kw)
  File "/usr/lib/python3.8/http/client.py", line 1256, in request
    self._send_request(method, url, body, headers, encode_chunked)
  File "/usr/lib/python3.8/http/client.py", line 1302, in _send_request
    self.endheaders(body, encode_chunked=encode_chunked)
  File "/usr/lib/python3.8/http/client.py", line 1251, in endheaders
    self._send_output(message_body, encode_chunked=encode_chunked)
  File "/usr/lib/python3.8/http/client.py", line 1011, in _send_output
    self.send(msg)
  File "/usr/lib/python3.8/http/client.py", line 951, in send
    self.connect()
  File "/usr/lib/python3/dist-packages/urllib3/connection.py", line 187, in connect
    conn = self._new_conn()
  File "/usr/lib/python3/dist-packages/urllib3/connection.py", line 171, in _new_conn
    raise NewConnectionError(
urllib3.exceptions.NewConnectionError: <urllib3.connection.HTTPConnection object at 0x766741103190>: Failed to establish a new connection: [Errno 111] Connection refused

During handling of the above exception, another exception occurred:

Traceback (most recent call last):
  File "/usr/lib/python3/dist-packages/requests/adapters.py", line 439, in send
    resp = conn.urlopen(
  File "/usr/lib/python3/dist-packages/urllib3/connectionpool.py", line 719, in urlopen
    retries = retries.increment(
  File "/usr/lib/python3/dist-packages/urllib3/util/retry.py", line 436, in increment
    raise MaxRetryError(_pool, url, error or ResponseError(cause))
urllib3.exceptions.MaxRetryError: HTTPConnectionPool(host='localhost', port=8000): Max retries exceeded with url: /users.json (Caused by NewConnectionError('<urllib3.connection.HTTPConnection object at 0x766741103190>: Failed to establish a new connection: [Errno 111] Connection refused'))

During handling of the above exception, another exception occurred:

Traceback (most recent call last):
  File "/mnt/c/Users/manib/data_pipeline_project/pipeline.py", line 39, in <module>
    run_pipeline()
  File "/mnt/c/Users/manib/data_pipeline_project/pipeline.py", line 35, in run_pipeline
    data = fetch_data()
  File "/mnt/c/Users/manib/data_pipeline_project/pipeline.py", line 10, in fetch_data
    response = requests.get("http://localhost:8000/users.json")
  File "/usr/lib/python3/dist-packages/requests/api.py", line 75, in get
    return request('get', url, params=params, **kwargs)
  File "/usr/lib/python3/dist-packages/requests/api.py", line 60, in request
    return session.request(method=method, url=url, **kwargs)
  File "/usr/lib/python3/dist-packages/requests/sessions.py", line 533, in request
    resp = self.send(prep, **send_kwargs)
  File "/usr/lib/python3/dist-packages/requests/sessions.py", line 646, in send
    r = adapter.send(request, **kwargs)
  File "/usr/lib/python3/dist-packages/requests/adapters.py", line 516, in send
    raise ConnectionError(e, request=request)
requests.exceptions.ConnectionError: HTTPConnectionPool(host='localhost', port=8000): Max retries exceeded with url: /users.json (Caused by NewConnectionError('<urllib3.connection.HTTPConnection object at 0x766741103190>: Failed to establish a new connection: [Errno 111] Connection refused'))
INFO:root:Fetching data from API...
Traceback (most recent call last):
  File "/usr/lib/python3/dist-packages/urllib3/connection.py", line 159, in _new_conn
    conn = connection.create_connection(
  File "/usr/lib/python3/dist-packages/urllib3/util/connection.py", line 84, in create_connection
    raise err
  File "/usr/lib/python3/dist-packages/urllib3/util/connection.py", line 74, in create_connection
    sock.connect(sa)
ConnectionRefusedError: [Errno 111] Connection refused

During handling of the above exception, another exception occurred:

Traceback (most recent call last):
  File "/usr/lib/python3/dist-packages/urllib3/connectionpool.py", line 665, in urlopen
    httplib_response = self._make_request(
  File "/usr/lib/python3/dist-packages/urllib3/connectionpool.py", line 387, in _make_request
    conn.request(method, url, **httplib_request_kw)
  File "/usr/lib/python3.8/http/client.py", line 1256, in request
    self._send_request(method, url, body, headers, encode_chunked)
  File "/usr/lib/python3.8/http/client.py", line 1302, in _send_request
    self.endheaders(body, encode_chunked=encode_chunked)
  File "/usr/lib/python3.8/http/client.py", line 1251, in endheaders
    self._send_output(message_body, encode_chunked=encode_chunked)
  File "/usr/lib/python3.8/http/client.py", line 1011, in _send_output
    self.send(msg)
  File "/usr/lib/python3.8/http/client.py", line 951, in send
    self.connect()
  File "/usr/lib/python3/dist-packages/urllib3/connection.py", line 187, in connect
    conn = self._new_conn()
  File "/usr/lib/python3/dist-packages/urllib3/connection.py", line 171, in _new_conn
    raise NewConnectionError(
urllib3.exceptions.NewConnectionError: <urllib3.connection.HTTPConnection object at 0x7a324b586190>: Failed to establish a new connection: [Errno 111] Connection refused

During handling of the above exception, another exception occurred:

Traceback (most recent call last):
  File "/usr/lib/python3/dist-packages/requests/adapters.py", line 439, in send
    resp = conn.urlopen(
  File "/usr/lib/python3/dist-packages/urllib3/connectionpool.py", line 719, in urlopen
    retries = retries.increment(
  File "/usr/lib/python3/dist-packages/urllib3/util/retry.py", line 436, in increment
    raise MaxRetryError(_pool, url, error or ResponseError(cause))
urllib3.exceptions.MaxRetryError: HTTPConnectionPool(host='localhost', port=8000): Max retries exceeded with url: /users.json (Caused by NewConnectionError('<urllib3.connection.HTTPConnection object at 0x7a324b586190>: Failed to establish a new connection: [Errno 111] Connection refused'))

During handling of the above exception, another exception occurred:

Traceback (most recent call last):
  File "/mnt/c/Users/manib/data_pipeline_project/pipeline.py", line 39, in <module>
    run_pipeline()
  File "/mnt/c/Users/manib/data_pipeline_project/pipeline.py", line 35, in run_pipeline
    data = fetch_data()
  File "/mnt/c/Users/manib/data_pipeline_project/pipeline.py", line 10, in fetch_data
    response = requests.get("http://localhost:8000/users.json")
  File "/usr/lib/python3/dist-packages/requests/api.py", line 75, in get
    return request('get', url, params=params, **kwargs)
  File "/usr/lib/python3/dist-packages/requests/api.py", line 60, in request
    return session.request(method=method, url=url, **kwargs)
  File "/usr/lib/python3/dist-packages/requests/sessions.py", line 533, in request
    resp = self.send(prep, **send_kwargs)
  File "/usr/lib/python3/dist-packages/requests/sessions.py", line 646, in send
    r = adapter.send(request, **kwargs)
  File "/usr/lib/python3/dist-packages/requests/adapters.py", line 516, in send
    raise ConnectionError(e, request=request)
requests.exceptions.ConnectionError: HTTPConnectionPool(host='localhost', port=8000): Max retries exceeded with url: /users.json (Caused by NewConnectionError('<urllib3.connection.HTTPConnection object at 0x7a324b586190>: Failed to establish a new connection: [Errno 111] Connection refused'))
INFO:root:Fetching data from API...
Traceback (most recent call last):
  File "/usr/lib/python3/dist-packages/urllib3/connection.py", line 159, in _new_conn
    conn = connection.create_connection(
  File "/usr/lib/python3/dist-packages/urllib3/util/connection.py", line 84, in create_connection
    raise err
  File "/usr/lib/python3/dist-packages/urllib3/util/connection.py", line 74, in create_connection
    sock.connect(sa)
ConnectionRefusedError: [Errno 111] Connection refused

During handling of the above exception, another exception occurred:

Traceback (most recent call last):
  File "/usr/lib/python3/dist-packages/urllib3/connectionpool.py", line 665, in urlopen
    httplib_response = self._make_request(
  File "/usr/lib/python3/dist-packages/urllib3/connectionpool.py", line 387, in _make_request
    conn.request(method, url, **httplib_request_kw)
  File "/usr/lib/python3.8/http/client.py", line 1256, in request
    self._send_request(method, url, body, headers, encode_chunked)
  File "/usr/lib/python3.8/http/client.py", line 1302, in _send_request
    self.endheaders(body, encode_chunked=encode_chunked)
  File "/usr/lib/python3.8/http/client.py", line 1251, in endheaders
    self._send_output(message_body, encode_chunked=encode_chunked)
  File "/usr/lib/python3.8/http/client.py", line 1011, in _send_output
    self.send(msg)
  File "/usr/lib/python3.8/http/client.py", line 951, in send
    self.connect()
  File "/usr/lib/python3/dist-packages/urllib3/connection.py", line 187, in connect
    conn = self._new_conn()
  File "/usr/lib/python3/dist-packages/urllib3/connection.py", line 171, in _new_conn
    raise NewConnectionError(
urllib3.exceptions.NewConnectionError: <urllib3.connection.HTTPConnection object at 0x7bea4ad41190>: Failed to establish a new connection: [Errno 111] Connection refused

During handling of the above exception, another exception occurred:

Traceback (most recent call last):
  File "/usr/lib/python3/dist-packages/requests/adapters.py", line 439, in send
    resp = conn.urlopen(
  File "/usr/lib/python3/dist-packages/urllib3/connectionpool.py", line 719, in urlopen
    retries = retries.increment(
  File "/usr/lib/python3/dist-packages/urllib3/util/retry.py", line 436, in increment
    raise MaxRetryError(_pool, url, error or ResponseError(cause))
urllib3.exceptions.MaxRetryError: HTTPConnectionPool(host='localhost', port=8000): Max retries exceeded with url: /users.json (Caused by NewConnectionError('<urllib3.connection.HTTPConnection object at 0x7bea4ad41190>: Failed to establish a new connection: [Errno 111] Connection refused'))

During handling of the above exception, another exception occurred:

Traceback (most recent call last):
  File "/mnt/c/Users/manib/data_pipeline_project/pipeline.py", line 39, in <module>
    run_pipeline()
  File "/mnt/c/Users/manib/data_pipeline_project/pipeline.py", line 35, in run_pipeline
    data = fetch_data()
  File "/mnt/c/Users/manib/data_pipeline_project/pipeline.py", line 10, in fetch_data
    response = requests.get("http://localhost:8000/users.json")
  File "/usr/lib/python3/dist-packages/requests/api.py", line 75, in get
    return request('get', url, params=params, **kwargs)
  File "/usr/lib/python3/dist-packages/requests/api.py", line 60, in request
    return session.request(method=method, url=url, **kwargs)
  File "/usr/lib/python3/dist-packages/requests/sessions.py", line 533, in request
    resp = self.send(prep, **send_kwargs)
  File "/usr/lib/python3/dist-packages/requests/sessions.py", line 646, in send
    r = adapter.send(request, **kwargs)
  File "/usr/lib/python3/dist-packages/requests/adapters.py", line 516, in send
    raise ConnectionError(e, request=request)
requests.exceptions.ConnectionError: HTTPConnectionPool(host='localhost', port=8000): Max retries exceeded with url: /users.json (Caused by NewConnectionError('<urllib3.connection.HTTPConnection object at 0x7bea4ad41190>: Failed to establish a new connection: [Errno 111] Connection refused'))
nohup: ignoring input
INFO:root:Fetching data from API...
Traceback (most recent call last):
  File "/usr/lib/python3/dist-packages/urllib3/connection.py", line 159, in _new_conn
    conn = connection.create_connection(
  File "/usr/lib/python3/dist-packages/urllib3/util/connection.py", line 84, in create_connection
    raise err
  File "/usr/lib/python3/dist-packages/urllib3/util/connection.py", line 74, in create_connection
    sock.connect(sa)
ConnectionRefusedError: [Errno 111] Connection refused

During handling of the above exception, another exception occurred:

Traceback (most recent call last):
  File "/usr/lib/python3/dist-packages/urllib3/connectionpool.py", line 665, in urlopen
    httplib_response = self._make_request(
  File "/usr/lib/python3/dist-packages/urllib3/connectionpool.py", line 387, in _make_request
    conn.request(method, url, **httplib_request_kw)
  File "/usr/lib/python3.8/http/client.py", line 1256, in request
    self._send_request(method, url, body, headers, encode_chunked)
  File "/usr/lib/python3.8/http/client.py", line 1302, in _send_request
    self.endheaders(body, encode_chunked=encode_chunked)
  File "/usr/lib/python3.8/http/client.py", line 1251, in endheaders
    self._send_output(message_body, encode_chunked=encode_chunked)
  File "/usr/lib/python3.8/http/client.py", line 1011, in _send_output
    self.send(msg)
  File "/usr/lib/python3.8/http/client.py", line 951, in send
    self.connect()
  File "/usr/lib/python3/dist-packages/urllib3/connection.py", line 187, in connect
    conn = self._new_conn()
  File "/usr/lib/python3/dist-packages/urllib3/connection.py", line 171, in _new_conn
    raise NewConnectionError(
urllib3.exceptions.NewConnectionError: <urllib3.connection.HTTPConnection object at 0x7834297fb6d0>: Failed to establish a new connection: [Errno 111] Connection refused

During handling of the above exception, another exception occurred:

Traceback (most recent call last):
  File "/usr/lib/python3/dist-packages/requests/adapters.py", line 439, in send
    resp = conn.urlopen(
  File "/usr/lib/python3/dist-packages/urllib3/connectionpool.py", line 719, in urlopen
    retries = retries.increment(
  File "/usr/lib/python3/dist-packages/urllib3/util/retry.py", line 436, in increment
    raise MaxRetryError(_pool, url, error or ResponseError(cause))
urllib3.exceptions.MaxRetryError: HTTPConnectionPool(host='localhost', port=8000): Max retries exceeded with url: /users.json (Caused by NewConnectionError('<urllib3.connection.HTTPConnection object at 0x7834297fb6d0>: Failed to establish a new connection: [Errno 111] Connection refused'))

During handling of the above exception, another exception occurred:

Traceback (most recent call last):
  File "/mnt/c/Users/manib/data_pipeline_project/pipeline.py", line 39, in <module>
    run_pipeline()
  File "/mnt/c/Users/manib/data_pipeline_project/pipeline.py", line 35, in run_pipeline
    data = fetch_data()
  File "/mnt/c/Users/manib/data_pipeline_project/pipeline.py", line 10, in fetch_data
    response = requests.get("http://localhost:8000/users.json")
  File "/usr/lib/python3/dist-packages/requests/api.py", line 75, in get
    return request('get', url, params=params, **kwargs)
  File "/usr/lib/python3/dist-packages/requests/api.py", line 60, in request
    return session.request(method=method, url=url, **kwargs)
  File "/usr/lib/python3/dist-packages/requests/sessions.py", line 533, in request
    resp = self.send(prep, **send_kwargs)
  File "/usr/lib/python3/dist-packages/requests/sessions.py", line 646, in send
    r = adapter.send(request, **kwargs)
  File "/usr/lib/python3/dist-packages/requests/adapters.py", line 516, in send
    raise ConnectionError(e, request=request)
requests.exceptions.ConnectionError: HTTPConnectionPool(host='localhost', port=8000): Max retries exceeded with url: /users.json (Caused by NewConnectionError('<urllib3.connection.HTTPConnection object at 0x7834297fb6d0>: Failed to establish a new connection: [Errno 111] Connection refused'))
INFO:root:Fetching data from API...
Traceback (most recent call last):
  File "/usr/lib/python3/dist-packages/urllib3/connection.py", line 159, in _new_conn
    conn = connection.create_connection(
  File "/usr/lib/python3/dist-packages/urllib3/util/connection.py", line 84, in create_connection
    raise err
  File "/usr/lib/python3/dist-packages/urllib3/util/connection.py", line 74, in create_connection
    sock.connect(sa)
ConnectionRefusedError: [Errno 111] Connection refused

During handling of the above exception, another exception occurred:

Traceback (most recent call last):
  File "/usr/lib/python3/dist-packages/urllib3/connectionpool.py", line 665, in urlopen
    httplib_response = self._make_request(
  File "/usr/lib/python3/dist-packages/urllib3/connectionpool.py", line 387, in _make_request
    conn.request(method, url, **httplib_request_kw)
  File "/usr/lib/python3.8/http/client.py", line 1256, in request
    self._send_request(method, url, body, headers, encode_chunked)
  File "/usr/lib/python3.8/http/client.py", line 1302, in _send_request
    self.endheaders(body, encode_chunked=encode_chunked)
  File "/usr/lib/python3.8/http/client.py", line 1251, in endheaders
    self._send_output(message_body, encode_chunked=encode_chunked)
  File "/usr/lib/python3.8/http/client.py", line 1011, in _send_output
    self.send(msg)
  File "/usr/lib/python3.8/http/client.py", line 951, in send
    self.connect()
  File "/usr/lib/python3/dist-packages/urllib3/connection.py", line 187, in connect
    conn = self._new_conn()
  File "/usr/lib/python3/dist-packages/urllib3/connection.py", line 171, in _new_conn
    raise NewConnectionError(
urllib3.exceptions.NewConnectionError: <urllib3.connection.HTTPConnection object at 0x7215d67c6190>: Failed to establish a new connection: [Errno 111] Connection refused

During handling of the above exception, another exception occurred:

Traceback (most recent call last):
  File "/usr/lib/python3/dist-packages/requests/adapters.py", line 439, in send
    resp = conn.urlopen(
  File "/usr/lib/python3/dist-packages/urllib3/connectionpool.py", line 719, in urlopen
    retries = retries.increment(
  File "/usr/lib/python3/dist-packages/urllib3/util/retry.py", line 436, in increment
    raise MaxRetryError(_pool, url, error or ResponseError(cause))
urllib3.exceptions.MaxRetryError: HTTPConnectionPool(host='localhost', port=8000): Max retries exceeded with url: /users.json (Caused by NewConnectionError('<urllib3.connection.HTTPConnection object at 0x7215d67c6190>: Failed to establish a new connection: [Errno 111] Connection refused'))

During handling of the above exception, another exception occurred:

Traceback (most recent call last):
  File "/mnt/c/Users/manib/data_pipeline_project/pipeline.py", line 39, in <module>
    run_pipeline()
  File "/mnt/c/Users/manib/data_pipeline_project/pipeline.py", line 35, in run_pipeline
    data = fetch_data()
  File "/mnt/c/Users/manib/data_pipeline_project/pipeline.py", line 10, in fetch_data
    response = requests.get("http://localhost:8000/users.json")
  File "/usr/lib/python3/dist-packages/requests/api.py", line 75, in get
    return request('get', url, params=params, **kwargs)
  File "/usr/lib/python3/dist-packages/requests/api.py", line 60, in request
    return session.request(method=method, url=url, **kwargs)
  File "/usr/lib/python3/dist-packages/requests/sessions.py", line 533, in request
    resp = self.send(prep, **send_kwargs)
  File "/usr/lib/python3/dist-packages/requests/sessions.py", line 646, in send
    r = adapter.send(request, **kwargs)
  File "/usr/lib/python3/dist-packages/requests/adapters.py", line 516, in send
    raise ConnectionError(e, request=request)
requests.exceptions.ConnectionError: HTTPConnectionPool(host='localhost', port=8000): Max retries exceeded with url: /users.json (Caused by NewConnectionError('<urllib3.connection.HTTPConnection object at 0x7215d67c6190>: Failed to establish a new connection: [Errno 111] Connection refused'))
INFO:root:Fetching data from API...
Traceback (most recent call last):
  File "/usr/lib/python3/dist-packages/urllib3/connection.py", line 159, in _new_conn
    conn = connection.create_connection(
  File "/usr/lib/python3/dist-packages/urllib3/util/connection.py", line 84, in create_connection
    raise err
  File "/usr/lib/python3/dist-packages/urllib3/util/connection.py", line 74, in create_connection
    sock.connect(sa)
ConnectionRefusedError: [Errno 111] Connection refused

During handling of the above exception, another exception occurred:

Traceback (most recent call last):
  File "/usr/lib/python3/dist-packages/urllib3/connectionpool.py", line 665, in urlopen
    httplib_response = self._make_request(
  File "/usr/lib/python3/dist-packages/urllib3/connectionpool.py", line 387, in _make_request
    conn.request(method, url, **httplib_request_kw)
  File "/usr/lib/python3.8/http/client.py", line 1256, in request
    self._send_request(method, url, body, headers, encode_chunked)
  File "/usr/lib/python3.8/http/client.py", line 1302, in _send_request
    self.endheaders(body, encode_chunked=encode_chunked)
  File "/usr/lib/python3.8/http/client.py", line 1251, in endheaders
    self._send_output(message_body, encode_chunked=encode_chunked)
  File "/usr/lib/python3.8/http/client.py", line 1011, in _send_output
    self.send(msg)
  File "/usr/lib/python3.8/http/client.py", line 951, in send
    self.connect()
  File "/usr/lib/python3/dist-packages/urllib3/connection.py", line 187, in connect
    conn = self._new_conn()
  File "/usr/lib/python3/dist-packages/urllib3/connection.py", line 171, in _new_conn
    raise NewConnectionError(
urllib3.exceptions.NewConnectionError: <urllib3.connection.HTTPConnection object at 0x7dd9de746190>: Failed to establish a new connection: [Errno 111] Connection refused

During handling of the above exception, another exception occurred:

Traceback (most recent call last):
  File "/usr/lib/python3/dist-packages/requests/adapters.py", line 439, in send
    resp = conn.urlopen(
  File "/usr/lib/python3/dist-packages/urllib3/connectionpool.py", line 719, in urlopen
    retries = retries.increment(
  File "/usr/lib/python3/dist-packages/urllib3/util/retry.py", line 436, in increment
    raise MaxRetryError(_pool, url, error or ResponseError(cause))
urllib3.exceptions.MaxRetryError: HTTPConnectionPool(host='localhost', port=8000): Max retries exceeded with url: /users.json (Caused by NewConnectionError('<urllib3.connection.HTTPConnection object at 0x7dd9de746190>: Failed to establish a new connection: [Errno 111] Connection refused'))

During handling of the above exception, another exception occurred:

Traceback (most recent call last):
  File "/mnt/c/Users/manib/data_pipeline_project/pipeline.py", line 39, in <module>
    run_pipeline()
  File "/mnt/c/Users/manib/data_pipeline_project/pipeline.py", line 35, in run_pipeline
    data = fetch_data()
  File "/mnt/c/Users/manib/data_pipeline_project/pipeline.py", line 10, in fetch_data
    response = requests.get("http://localhost:8000/users.json")
  File "/usr/lib/python3/dist-packages/requests/api.py", line 75, in get
    return request('get', url, params=params, **kwargs)
  File "/usr/lib/python3/dist-packages/requests/api.py", line 60, in request
    return session.request(method=method, url=url, **kwargs)
  File "/usr/lib/python3/dist-packages/requests/sessions.py", line 533, in request
    resp = self.send(prep, **send_kwargs)
  File "/usr/lib/python3/dist-packages/requests/sessions.py", line 646, in send
    r = adapter.send(request, **kwargs)
  File "/usr/lib/python3/dist-packages/requests/adapters.py", line 516, in send
    raise ConnectionError(e, request=request)
requests.exceptions.ConnectionError: HTTPConnectionPool(host='localhost', port=8000): Max retries exceeded with url: /users.json (Caused by NewConnectionError('<urllib3.connection.HTTPConnection object at 0x7dd9de746190>: Failed to establish a new connection: [Errno 111] Connection refused'))
INFO:root:Fetching data from API...
Traceback (most recent call last):
  File "/mnt/c/Users/manib/data_pipeline_project/pipeline.py", line 39, in <module>
    run_pipeline()
  File "/mnt/c/Users/manib/data_pipeline_project/pipeline.py", line 35, in run_pipeline
    data = fetch_data()
  File "/mnt/c/Users/manib/data_pipeline_project/pipeline.py", line 12, in fetch_data
    response.raise_for_status()
  File "/usr/lib/python3/dist-packages/requests/models.py", line 940, in raise_for_status
    raise HTTPError(http_error_msg, response=self)
requests.exceptions.HTTPError: 404 Client Error: File not found for url: http://localhost:8000/users.json
INFO:root:Fetching data from API...
Traceback (most recent call last):
  File "/mnt/c/Users/manib/data_pipeline_project/pipeline.py", line 39, in <module>
    run_pipeline()
  File "/mnt/c/Users/manib/data_pipeline_project/pipeline.py", line 35, in run_pipeline
    data = fetch_data()
  File "/mnt/c/Users/manib/data_pipeline_project/pipeline.py", line 12, in fetch_data
    response.raise_for_status()
  File "/usr/lib/python3/dist-packages/requests/models.py", line 940, in raise_for_status
    raise HTTPError(http_error_msg, response=self)
requests.exceptions.HTTPError: 404 Client Error: File not found for url: http://localhost:8000/users.json
INFO:root:Fetching data from API...
Traceback (most recent call last):
  File "/mnt/c/Users/manib/data_pipeline_project/pipeline.py", line 39, in <module>
    run_pipeline()
  File "/mnt/c/Users/manib/data_pipeline_project/pipeline.py", line 35, in run_pipeline
    data = fetch_data()
  File "/mnt/c/Users/manib/data_pipeline_project/pipeline.py", line 12, in fetch_data
    response.raise_for_status()
  File "/usr/lib/python3/dist-packages/requests/models.py", line 940, in raise_for_status
    raise HTTPError(http_error_msg, response=self)
requests.exceptions.HTTPError: 404 Client Error: File not found for url: http://localhost:8000/users.json
INFO:root:Fetching data from API...
Traceback (most recent call last):
  File "/mnt/c/Users/manib/data_pipeline_project/pipeline.py", line 39, in <module>
    run_pipeline()
  File "/mnt/c/Users/manib/data_pipeline_project/pipeline.py", line 35, in run_pipeline
    data = fetch_data()
  File "/mnt/c/Users/manib/data_pipeline_project/pipeline.py", line 12, in fetch_data
    response.raise_for_status()
  File "/usr/lib/python3/dist-packages/requests/models.py", line 940, in raise_for_status
    raise HTTPError(http_error_msg, response=self)
requests.exceptions.HTTPError: 404 Client Error: File not found for url: http://localhost:8000/users.json
INFO:root:Fetching data from API...
Traceback (most recent call last):
  File "/mnt/c/Users/manib/data_pipeline_project/pipeline.py", line 39, in <module>
    run_pipeline()
  File "/mnt/c/Users/manib/data_pipeline_project/pipeline.py", line 35, in run_pipeline
    data = fetch_data()
  File "/mnt/c/Users/manib/data_pipeline_project/pipeline.py", line 12, in fetch_data
    response.raise_for_status()
  File "/usr/lib/python3/dist-packages/requests/models.py", line 940, in raise_for_status
    raise HTTPError(http_error_msg, response=self)
requests.exceptions.HTTPError: 404 Client Error: File not found for url: http://localhost:8000/users.json
INFO:root:Fetching data from API...
Traceback (most recent call last):
  File "/mnt/c/Users/manib/data_pipeline_project/pipeline.py", line 39, in <module>
    run_pipeline()
  File "/mnt/c/Users/manib/data_pipeline_project/pipeline.py", line 35, in run_pipeline
    data = fetch_data()
  File "/mnt/c/Users/manib/data_pipeline_project/pipeline.py", line 12, in fetch_data
    response.raise_for_status()
  File "/usr/lib/python3/dist-packages/requests/models.py", line 940, in raise_for_status
    raise HTTPError(http_error_msg, response=self)
requests.exceptions.HTTPError: 404 Client Error: File not found for url: http://localhost:8000/users.json
INFO:root:Fetching data from API...
Traceback (most recent call last):
  File "/mnt/c/Users/manib/data_pipeline_project/pipeline.py", line 39, in <module>
    run_pipeline()
  File "/mnt/c/Users/manib/data_pipeline_project/pipeline.py", line 35, in run_pipeline
    data = fetch_data()
  File "/mnt/c/Users/manib/data_pipeline_project/pipeline.py", line 12, in fetch_data
    response.raise_for_status()
  File "/usr/lib/python3/dist-packages/requests/models.py", line 940, in raise_for_status
    raise HTTPError(http_error_msg, response=self)
requests.exceptions.HTTPError: 404 Client Error: File not found for url: http://localhost:8000/users.json
INFO:root:Fetching data from API...
Traceback (most recent call last):
  File "/mnt/c/Users/manib/data_pipeline_project/pipeline.py", line 39, in <module>
    run_pipeline()
  File "/mnt/c/Users/manib/data_pipeline_project/pipeline.py", line 35, in run_pipeline
    data = fetch_data()
  File "/mnt/c/Users/manib/data_pipeline_project/pipeline.py", line 12, in fetch_data
    response.raise_for_status()
  File "/usr/lib/python3/dist-packages/requests/models.py", line 940, in raise_for_status
    raise HTTPError(http_error_msg, response=self)
requests.exceptions.HTTPError: 404 Client Error: File not found for url: http://localhost:8000/users.json
INFO:root:Fetching data from API...
Traceback (most recent call last):
  File "/mnt/c/Users/manib/data_pipeline_project/pipeline.py", line 39, in <module>
    run_pipeline()
  File "/mnt/c/Users/manib/data_pipeline_project/pipeline.py", line 35, in run_pipeline
    data = fetch_data()
  File "/mnt/c/Users/manib/data_pipeline_project/pipeline.py", line 12, in fetch_data
    response.raise_for_status()
  File "/usr/lib/python3/dist-packages/requests/models.py", line 940, in raise_for_status
    raise HTTPError(http_error_msg, response=self)
requests.exceptions.HTTPError: 404 Client Error: File not found for url: http://localhost:8000/users.json
INFO:root:Fetching data from API...
Traceback (most recent call last):
  File "/mnt/c/Users/manib/data_pipeline_project/pipeline.py", line 39, in <module>
    run_pipeline()
  File "/mnt/c/Users/manib/data_pipeline_project/pipeline.py", line 35, in run_pipeline
    data = fetch_data()
  File "/mnt/c/Users/manib/data_pipeline_project/pipeline.py", line 12, in fetch_data
    response.raise_for_status()
  File "/usr/lib/python3/dist-packages/requests/models.py", line 940, in raise_for_status
    raise HTTPError(http_error_msg, response=self)
requests.exceptions.HTTPError: 404 Client Error: File not found for url: http://localhost:8000/users.json
INFO:root:Fetching data from API...
Traceback (most recent call last):
  File "/mnt/c/Users/manib/data_pipeline_project/pipeline.py", line 39, in <module>
    run_pipeline()
  File "/mnt/c/Users/manib/data_pipeline_project/pipeline.py", line 35, in run_pipeline
    data = fetch_data()
  File "/mnt/c/Users/manib/data_pipeline_project/pipeline.py", line 12, in fetch_data
    response.raise_for_status()
  File "/usr/lib/python3/dist-packages/requests/models.py", line 940, in raise_for_status
    raise HTTPError(http_error_msg, response=self)
requests.exceptions.HTTPError: 404 Client Error: File not found for url: http://localhost:8000/users.json
INFO:root:Fetching data from API...
Traceback (most recent call last):
  File "/mnt/c/Users/manib/data_pipeline_project/pipeline.py", line 39, in <module>
    run_pipeline()
  File "/mnt/c/Users/manib/data_pipeline_project/pipeline.py", line 35, in run_pipeline
    data = fetch_data()
  File "/mnt/c/Users/manib/data_pipeline_project/pipeline.py", line 12, in fetch_data
    response.raise_for_status()
  File "/usr/lib/python3/dist-packages/requests/models.py", line 940, in raise_for_status
    raise HTTPError(http_error_msg, response=self)
requests.exceptions.HTTPError: 404 Client Error: File not found for url: http://localhost:8000/users.json
INFO:root:Fetching data from API...
Traceback (most recent call last):
  File "/mnt/c/Users/manib/data_pipeline_project/pipeline.py", line 39, in <module>
    run_pipeline()
  File "/mnt/c/Users/manib/data_pipeline_project/pipeline.py", line 35, in run_pipeline
    data = fetch_data()
  File "/mnt/c/Users/manib/data_pipeline_project/pipeline.py", line 12, in fetch_data
    response.raise_for_status()
  File "/usr/lib/python3/dist-packages/requests/models.py", line 940, in raise_for_status
    raise HTTPError(http_error_msg, response=self)
requests.exceptions.HTTPError: 404 Client Error: File not found for url: http://localhost:8000/users.json
INFO:root:Fetching data from API...
Traceback (most recent call last):
  File "/mnt/c/Users/manib/data_pipeline_project/pipeline.py", line 39, in <module>
    run_pipeline()
  File "/mnt/c/Users/manib/data_pipeline_project/pipeline.py", line 35, in run_pipeline
    data = fetch_data()
  File "/mnt/c/Users/manib/data_pipeline_project/pipeline.py", line 12, in fetch_data
    response.raise_for_status()
  File "/usr/lib/python3/dist-packages/requests/models.py", line 940, in raise_for_status
    raise HTTPError(http_error_msg, response=self)
requests.exceptions.HTTPError: 404 Client Error: File not found for url: http://localhost:8000/users.json
INFO:root:Fetching data from API...
Traceback (most recent call last):
  File "/mnt/c/Users/manib/data_pipeline_project/pipeline.py", line 39, in <module>
    run_pipeline()
  File "/mnt/c/Users/manib/data_pipeline_project/pipeline.py", line 35, in run_pipeline
    data = fetch_data()
  File "/mnt/c/Users/manib/data_pipeline_project/pipeline.py", line 12, in fetch_data
    response.raise_for_status()
  File "/usr/lib/python3/dist-packages/requests/models.py", line 940, in raise_for_status
    raise HTTPError(http_error_msg, response=self)
requests.exceptions.HTTPError: 404 Client Error: File not found for url: http://localhost:8000/users.json
INFO:root:Fetching data from API...
Traceback (most recent call last):
  File "/mnt/c/Users/manib/data_pipeline_project/pipeline.py", line 39, in <module>
    run_pipeline()
  File "/mnt/c/Users/manib/data_pipeline_project/pipeline.py", line 35, in run_pipeline
    data = fetch_data()
  File "/mnt/c/Users/manib/data_pipeline_project/pipeline.py", line 12, in fetch_data
    response.raise_for_status()
  File "/usr/lib/python3/dist-packages/requests/models.py", line 940, in raise_for_status
    raise HTTPError(http_error_msg, response=self)
requests.exceptions.HTTPError: 404 Client Error: File not found for url: http://localhost:8000/users.json
INFO:root:Fetching data from API...
Traceback (most recent call last):
  File "/mnt/c/Users/manib/data_pipeline_project/pipeline.py", line 39, in <module>
    run_pipeline()
  File "/mnt/c/Users/manib/data_pipeline_project/pipeline.py", line 35, in run_pipeline
    data = fetch_data()
  File "/mnt/c/Users/manib/data_pipeline_project/pipeline.py", line 12, in fetch_data
    response.raise_for_status()
  File "/usr/lib/python3/dist-packages/requests/models.py", line 940, in raise_for_status
    raise HTTPError(http_error_msg, response=self)
requests.exceptions.HTTPError: 404 Client Error: File not found for url: http://localhost:8000/users.json
INFO:root:Fetching data from API...
Traceback (most recent call last):
  File "/mnt/c/Users/manib/data_pipeline_project/pipeline.py", line 39, in <module>
    run_pipeline()
  File "/mnt/c/Users/manib/data_pipeline_project/pipeline.py", line 35, in run_pipeline
    data = fetch_data()
  File "/mnt/c/Users/manib/data_pipeline_project/pipeline.py", line 12, in fetch_data
    response.raise_for_status()
  File "/usr/lib/python3/dist-packages/requests/models.py", line 940, in raise_for_status
    raise HTTPError(http_error_msg, response=self)
requests.exceptions.HTTPError: 404 Client Error: File not found for url: http://localhost:8000/users.json
INFO:root:Fetching data from API...
Traceback (most recent call last):
  File "/mnt/c/Users/manib/data_pipeline_project/pipeline.py", line 39, in <module>
    run_pipeline()
  File "/mnt/c/Users/manib/data_pipeline_project/pipeline.py", line 35, in run_pipeline
    data = fetch_data()
  File "/mnt/c/Users/manib/data_pipeline_project/pipeline.py", line 12, in fetch_data
    response.raise_for_status()
  File "/usr/lib/python3/dist-packages/requests/models.py", line 940, in raise_for_status
    raise HTTPError(http_error_msg, response=self)
requests.exceptions.HTTPError: 404 Client Error: File not found for url: http://localhost:8000/users.json
INFO:root:Fetching data from API...
Traceback (most recent call last):
  File "/mnt/c/Users/manib/data_pipeline_project/pipeline.py", line 39, in <module>
    run_pipeline()
  File "/mnt/c/Users/manib/data_pipeline_project/pipeline.py", line 35, in run_pipeline
    data = fetch_data()
  File "/mnt/c/Users/manib/data_pipeline_project/pipeline.py", line 12, in fetch_data
    response.raise_for_status()
  File "/usr/lib/python3/dist-packages/requests/models.py", line 940, in raise_for_status
    raise HTTPError(http_error_msg, response=self)
requests.exceptions.HTTPError: 404 Client Error: File not found for url: http://localhost:8000/users.json
INFO:root:Fetching data from API...
Traceback (most recent call last):
  File "/mnt/c/Users/manib/data_pipeline_project/pipeline.py", line 39, in <module>
    run_pipeline()
  File "/mnt/c/Users/manib/data_pipeline_project/pipeline.py", line 35, in run_pipeline
    data = fetch_data()
  File "/mnt/c/Users/manib/data_pipeline_project/pipeline.py", line 12, in fetch_data
    response.raise_for_status()
  File "/usr/lib/python3/dist-packages/requests/models.py", line 940, in raise_for_status
    raise HTTPError(http_error_msg, response=self)
requests.exceptions.HTTPError: 404 Client Error: File not found for url: http://localhost:8000/users.json
INFO:root:Fetching data from API...
Traceback (most recent call last):
  File "/mnt/c/Users/manib/data_pipeline_project/pipeline.py", line 39, in <module>
    run_pipeline()
  File "/mnt/c/Users/manib/data_pipeline_project/pipeline.py", line 35, in run_pipeline
    data = fetch_data()
  File "/mnt/c/Users/manib/data_pipeline_project/pipeline.py", line 12, in fetch_data
    response.raise_for_status()
  File "/usr/lib/python3/dist-packages/requests/models.py", line 940, in raise_for_status
    raise HTTPError(http_error_msg, response=self)
requests.exceptions.HTTPError: 404 Client Error: File not found for url: http://localhost:8000/users.json
INFO:root:Fetching data from API...
Traceback (most recent call last):
  File "/mnt/c/Users/manib/data_pipeline_project/pipeline.py", line 39, in <module>
    run_pipeline()
  File "/mnt/c/Users/manib/data_pipeline_project/pipeline.py", line 35, in run_pipeline
    data = fetch_data()
  File "/mnt/c/Users/manib/data_pipeline_project/pipeline.py", line 12, in fetch_data
    response.raise_for_status()
  File "/usr/lib/python3/dist-packages/requests/models.py", line 940, in raise_for_status
    raise HTTPError(http_error_msg, response=self)
requests.exceptions.HTTPError: 404 Client Error: File not found for url: http://localhost:8000/users.json
INFO:root:Fetching data from API...
Traceback (most recent call last):
  File "/mnt/c/Users/manib/data_pipeline_project/pipeline.py", line 39, in <module>
    run_pipeline()
  File "/mnt/c/Users/manib/data_pipeline_project/pipeline.py", line 35, in run_pipeline
    data = fetch_data()
  File "/mnt/c/Users/manib/data_pipeline_project/pipeline.py", line 12, in fetch_data
    response.raise_for_status()
  File "/usr/lib/python3/dist-packages/requests/models.py", line 940, in raise_for_status
    raise HTTPError(http_error_msg, response=self)
requests.exceptions.HTTPError: 404 Client Error: File not found for url: http://localhost:8000/users.json
INFO:root:Fetching data from API...
Traceback (most recent call last):
  File "/mnt/c/Users/manib/data_pipeline_project/pipeline.py", line 39, in <module>
    run_pipeline()
  File "/mnt/c/Users/manib/data_pipeline_project/pipeline.py", line 35, in run_pipeline
    data = fetch_data()
  File "/mnt/c/Users/manib/data_pipeline_project/pipeline.py", line 12, in fetch_data
    response.raise_for_status()
  File "/usr/lib/python3/dist-packages/requests/models.py", line 940, in raise_for_status
    raise HTTPError(http_error_msg, response=self)
requests.exceptions.HTTPError: 404 Client Error: File not found for url: http://localhost:8000/users.json
INFO:root:Fetching data from API...
Traceback (most recent call last):
  File "/mnt/c/Users/manib/data_pipeline_project/pipeline.py", line 39, in <module>
    run_pipeline()
  File "/mnt/c/Users/manib/data_pipeline_project/pipeline.py", line 35, in run_pipeline
    data = fetch_data()
  File "/mnt/c/Users/manib/data_pipeline_project/pipeline.py", line 12, in fetch_data
    response.raise_for_status()
  File "/usr/lib/python3/dist-packages/requests/models.py", line 940, in raise_for_status
    raise HTTPError(http_error_msg, response=self)
requests.exceptions.HTTPError: 404 Client Error: File not found for url: http://localhost:8000/users.json
INFO:root:Fetching data from API...
Traceback (most recent call last):
  File "/mnt/c/Users/manib/data_pipeline_project/pipeline.py", line 39, in <module>
    run_pipeline()
  File "/mnt/c/Users/manib/data_pipeline_project/pipeline.py", line 35, in run_pipeline
    data = fetch_data()
  File "/mnt/c/Users/manib/data_pipeline_project/pipeline.py", line 12, in fetch_data
    response.raise_for_status()
  File "/usr/lib/python3/dist-packages/requests/models.py", line 940, in raise_for_status
    raise HTTPError(http_error_msg, response=self)
requests.exceptions.HTTPError: 404 Client Error: File not found for url: http://localhost:8000/users.json
INFO:root:Fetching data from API...
Traceback (most recent call last):
  File "/mnt/c/Users/manib/data_pipeline_project/pipeline.py", line 39, in <module>
    run_pipeline()
  File "/mnt/c/Users/manib/data_pipeline_project/pipeline.py", line 35, in run_pipeline
    data = fetch_data()
  File "/mnt/c/Users/manib/data_pipeline_project/pipeline.py", line 12, in fetch_data
    response.raise_for_status()
  File "/usr/lib/python3/dist-packages/requests/models.py", line 940, in raise_for_status
    raise HTTPError(http_error_msg, response=self)
requests.exceptions.HTTPError: 404 Client Error: File not found for url: http://localhost:8000/users.json
INFO:root:Fetching data from API...
Traceback (most recent call last):
  File "/mnt/c/Users/manib/data_pipeline_project/pipeline.py", line 39, in <module>
    run_pipeline()
  File "/mnt/c/Users/manib/data_pipeline_project/pipeline.py", line 35, in run_pipeline
    data = fetch_data()
  File "/mnt/c/Users/manib/data_pipeline_project/pipeline.py", line 12, in fetch_data
    response.raise_for_status()
  File "/usr/lib/python3/dist-packages/requests/models.py", line 940, in raise_for_status
    raise HTTPError(http_error_msg, response=self)
requests.exceptions.HTTPError: 404 Client Error: File not found for url: http://localhost:8000/users.json
INFO:root:Fetching data from API...
Traceback (most recent call last):
  File "/mnt/c/Users/manib/data_pipeline_project/pipeline.py", line 39, in <module>
    run_pipeline()
  File "/mnt/c/Users/manib/data_pipeline_project/pipeline.py", line 35, in run_pipeline
    data = fetch_data()
  File "/mnt/c/Users/manib/data_pipeline_project/pipeline.py", line 12, in fetch_data
    response.raise_for_status()
  File "/usr/lib/python3/dist-packages/requests/models.py", line 940, in raise_for_status
    raise HTTPError(http_error_msg, response=self)
requests.exceptions.HTTPError: 404 Client Error: File not found for url: http://localhost:8000/users.json
INFO:root:Fetching data from API...
Traceback (most recent call last):
  File "/mnt/c/Users/manib/data_pipeline_project/pipeline.py", line 39, in <module>
    run_pipeline()
  File "/mnt/c/Users/manib/data_pipeline_project/pipeline.py", line 35, in run_pipeline
    data = fetch_data()
  File "/mnt/c/Users/manib/data_pipeline_project/pipeline.py", line 12, in fetch_data
    response.raise_for_status()
  File "/usr/lib/python3/dist-packages/requests/models.py", line 940, in raise_for_status
    raise HTTPError(http_error_msg, response=self)
requests.exceptions.HTTPError: 404 Client Error: File not found for url: http://localhost:8000/users.json
INFO:root:Fetching data from API...
Traceback (most recent call last):
  File "/mnt/c/Users/manib/data_pipeline_project/pipeline.py", line 39, in <module>
    run_pipeline()
  File "/mnt/c/Users/manib/data_pipeline_project/pipeline.py", line 35, in run_pipeline
    data = fetch_data()
  File "/mnt/c/Users/manib/data_pipeline_project/pipeline.py", line 12, in fetch_data
    response.raise_for_status()
  File "/usr/lib/python3/dist-packages/requests/models.py", line 940, in raise_for_status
    raise HTTPError(http_error_msg, response=self)
requests.exceptions.HTTPError: 404 Client Error: File not found for url: http://localhost:8000/users.json
INFO:root:Fetching data from API...
Traceback (most recent call last):
  File "/mnt/c/Users/manib/data_pipeline_project/pipeline.py", line 39, in <module>
    run_pipeline()
  File "/mnt/c/Users/manib/data_pipeline_project/pipeline.py", line 35, in run_pipeline
    data = fetch_data()
  File "/mnt/c/Users/manib/data_pipeline_project/pipeline.py", line 12, in fetch_data
    response.raise_for_status()
  File "/usr/lib/python3/dist-packages/requests/models.py", line 940, in raise_for_status
    raise HTTPError(http_error_msg, response=self)
requests.exceptions.HTTPError: 404 Client Error: File not found for url: http://localhost:8000/users.json
INFO:root:Fetching data from API...
Traceback (most recent call last):
  File "/mnt/c/Users/manib/data_pipeline_project/pipeline.py", line 39, in <module>
    run_pipeline()
  File "/mnt/c/Users/manib/data_pipeline_project/pipeline.py", line 35, in run_pipeline
    data = fetch_data()
  File "/mnt/c/Users/manib/data_pipeline_project/pipeline.py", line 12, in fetch_data
    response.raise_for_status()
  File "/usr/lib/python3/dist-packages/requests/models.py", line 940, in raise_for_status
    raise HTTPError(http_error_msg, response=self)
requests.exceptions.HTTPError: 404 Client Error: File not found for url: http://localhost:8000/users.json
INFO:root:Fetching data from API...
Traceback (most recent call last):
  File "/mnt/c/Users/manib/data_pipeline_project/pipeline.py", line 39, in <module>
    run_pipeline()
  File "/mnt/c/Users/manib/data_pipeline_project/pipeline.py", line 35, in run_pipeline
    data = fetch_data()
  File "/mnt/c/Users/manib/data_pipeline_project/pipeline.py", line 12, in fetch_data
    response.raise_for_status()
  File "/usr/lib/python3/dist-packages/requests/models.py", line 940, in raise_for_status
    raise HTTPError(http_error_msg, response=self)
requests.exceptions.HTTPError: 404 Client Error: File not found for url: http://localhost:8000/users.json
INFO:root:Fetching data from API...
Traceback (most recent call last):
  File "/mnt/c/Users/manib/data_pipeline_project/pipeline.py", line 39, in <module>
    run_pipeline()
  File "/mnt/c/Users/manib/data_pipeline_project/pipeline.py", line 35, in run_pipeline
    data = fetch_data()
  File "/mnt/c/Users/manib/data_pipeline_project/pipeline.py", line 12, in fetch_data
    response.raise_for_status()
  File "/usr/lib/python3/dist-packages/requests/models.py", line 940, in raise_for_status
    raise HTTPError(http_error_msg, response=self)
requests.exceptions.HTTPError: 404 Client Error: File not found for url: http://localhost:8000/users.json
INFO:root:Fetching data from API...
Traceback (most recent call last):
  File "/mnt/c/Users/manib/data_pipeline_project/pipeline.py", line 39, in <module>
    run_pipeline()
  File "/mnt/c/Users/manib/data_pipeline_project/pipeline.py", line 35, in run_pipeline
    data = fetch_data()
  File "/mnt/c/Users/manib/data_pipeline_project/pipeline.py", line 12, in fetch_data
    response.raise_for_status()
  File "/usr/lib/python3/dist-packages/requests/models.py", line 940, in raise_for_status
    raise HTTPError(http_error_msg, response=self)
requests.exceptions.HTTPError: 404 Client Error: File not found for url: http://localhost:8000/users.json
INFO:root:Fetching data from API...
Traceback (most recent call last):
  File "/mnt/c/Users/manib/data_pipeline_project/pipeline.py", line 39, in <module>
    run_pipeline()
  File "/mnt/c/Users/manib/data_pipeline_project/pipeline.py", line 35, in run_pipeline
    data = fetch_data()
  File "/mnt/c/Users/manib/data_pipeline_project/pipeline.py", line 12, in fetch_data
    response.raise_for_status()
  File "/usr/lib/python3/dist-packages/requests/models.py", line 940, in raise_for_status
    raise HTTPError(http_error_msg, response=self)
requests.exceptions.HTTPError: 404 Client Error: File not found for url: http://localhost:8000/users.json
INFO:root:Fetching data from API...
Traceback (most recent call last):
  File "/mnt/c/Users/manib/data_pipeline_project/pipeline.py", line 39, in <module>
    run_pipeline()
  File "/mnt/c/Users/manib/data_pipeline_project/pipeline.py", line 35, in run_pipeline
    data = fetch_data()
  File "/mnt/c/Users/manib/data_pipeline_project/pipeline.py", line 12, in fetch_data
    response.raise_for_status()
  File "/usr/lib/python3/dist-packages/requests/models.py", line 940, in raise_for_status
    raise HTTPError(http_error_msg, response=self)
requests.exceptions.HTTPError: 404 Client Error: File not found for url: http://localhost:8000/users.json
INFO:root:Fetching data from API...
Traceback (most recent call last):
  File "/mnt/c/Users/manib/data_pipeline_project/pipeline.py", line 39, in <module>
    run_pipeline()
  File "/mnt/c/Users/manib/data_pipeline_project/pipeline.py", line 35, in run_pipeline
    data = fetch_data()
  File "/mnt/c/Users/manib/data_pipeline_project/pipeline.py", line 12, in fetch_data
    response.raise_for_status()
  File "/usr/lib/python3/dist-packages/requests/models.py", line 940, in raise_for_status
    raise HTTPError(http_error_msg, response=self)
requests.exceptions.HTTPError: 404 Client Error: File not found for url: http://localhost:8000/users.json
INFO:root:Fetching data from API...
Traceback (most recent call last):
  File "/mnt/c/Users/manib/data_pipeline_project/pipeline.py", line 39, in <module>
    run_pipeline()
  File "/mnt/c/Users/manib/data_pipeline_project/pipeline.py", line 35, in run_pipeline
    data = fetch_data()
  File "/mnt/c/Users/manib/data_pipeline_project/pipeline.py", line 12, in fetch_data
    response.raise_for_status()
  File "/usr/lib/python3/dist-packages/requests/models.py", line 940, in raise_for_status
    raise HTTPError(http_error_msg, response=self)
requests.exceptions.HTTPError: 404 Client Error: File not found for url: http://localhost:8000/users.json
INFO:root:Fetching data from API...
Traceback (most recent call last):
  File "/mnt/c/Users/manib/data_pipeline_project/pipeline.py", line 39, in <module>
    run_pipeline()
  File "/mnt/c/Users/manib/data_pipeline_project/pipeline.py", line 35, in run_pipeline
    data = fetch_data()
  File "/mnt/c/Users/manib/data_pipeline_project/pipeline.py", line 12, in fetch_data
    response.raise_for_status()
  File "/usr/lib/python3/dist-packages/requests/models.py", line 940, in raise_for_status
    raise HTTPError(http_error_msg, response=self)
requests.exceptions.HTTPError: 404 Client Error: File not found for url: http://localhost:8000/users.json
INFO:root:Fetching data from API...
Traceback (most recent call last):
  File "/mnt/c/Users/manib/data_pipeline_project/pipeline.py", line 39, in <module>
    run_pipeline()
  File "/mnt/c/Users/manib/data_pipeline_project/pipeline.py", line 35, in run_pipeline
    data = fetch_data()
  File "/mnt/c/Users/manib/data_pipeline_project/pipeline.py", line 12, in fetch_data
    response.raise_for_status()
  File "/usr/lib/python3/dist-packages/requests/models.py", line 940, in raise_for_status
    raise HTTPError(http_error_msg, response=self)
requests.exceptions.HTTPError: 404 Client Error: File not found for url: http://localhost:8000/users.json
INFO:root:Fetching data from API...
Traceback (most recent call last):
  File "/mnt/c/Users/manib/data_pipeline_project/pipeline.py", line 39, in <module>
    run_pipeline()
  File "/mnt/c/Users/manib/data_pipeline_project/pipeline.py", line 35, in run_pipeline
    data = fetch_data()
  File "/mnt/c/Users/manib/data_pipeline_project/pipeline.py", line 12, in fetch_data
    response.raise_for_status()
  File "/usr/lib/python3/dist-packages/requests/models.py", line 940, in raise_for_status
    raise HTTPError(http_error_msg, response=self)
requests.exceptions.HTTPError: 404 Client Error: File not found for url: http://localhost:8000/users.json
INFO:root:Fetching data from API...
Traceback (most recent call last):
  File "/mnt/c/Users/manib/data_pipeline_project/pipeline.py", line 39, in <module>
    run_pipeline()
  File "/mnt/c/Users/manib/data_pipeline_project/pipeline.py", line 35, in run_pipeline
    data = fetch_data()
  File "/mnt/c/Users/manib/data_pipeline_project/pipeline.py", line 12, in fetch_data
    response.raise_for_status()
  File "/usr/lib/python3/dist-packages/requests/models.py", line 940, in raise_for_status
    raise HTTPError(http_error_msg, response=self)
requests.exceptions.HTTPError: 404 Client Error: File not found for url: http://localhost:8000/users.json
INFO:root:Fetching data from API...
Traceback (most recent call last):
  File "/mnt/c/Users/manib/data_pipeline_project/pipeline.py", line 39, in <module>
    run_pipeline()
  File "/mnt/c/Users/manib/data_pipeline_project/pipeline.py", line 35, in run_pipeline
    data = fetch_data()
  File "/mnt/c/Users/manib/data_pipeline_project/pipeline.py", line 12, in fetch_data
    response.raise_for_status()
  File "/usr/lib/python3/dist-packages/requests/models.py", line 940, in raise_for_status
    raise HTTPError(http_error_msg, response=self)
requests.exceptions.HTTPError: 404 Client Error: File not found for url: http://localhost:8000/users.json
INFO:root:Fetching data from API...
Traceback (most recent call last):
  File "/mnt/c/Users/manib/data_pipeline_project/pipeline.py", line 39, in <module>
    run_pipeline()
  File "/mnt/c/Users/manib/data_pipeline_project/pipeline.py", line 35, in run_pipeline
    data = fetch_data()
  File "/mnt/c/Users/manib/data_pipeline_project/pipeline.py", line 12, in fetch_data
    response.raise_for_status()
  File "/usr/lib/python3/dist-packages/requests/models.py", line 940, in raise_for_status
    raise HTTPError(http_error_msg, response=self)
requests.exceptions.HTTPError: 404 Client Error: File not found for url: http://localhost:8000/users.json
INFO:root:Fetching data from API...
Traceback (most recent call last):
  File "/mnt/c/Users/manib/data_pipeline_project/pipeline.py", line 39, in <module>
    run_pipeline()
  File "/mnt/c/Users/manib/data_pipeline_project/pipeline.py", line 35, in run_pipeline
    data = fetch_data()
  File "/mnt/c/Users/manib/data_pipeline_project/pipeline.py", line 12, in fetch_data
    response.raise_for_status()
  File "/usr/lib/python3/dist-packages/requests/models.py", line 940, in raise_for_status
    raise HTTPError(http_error_msg, response=self)
requests.exceptions.HTTPError: 404 Client Error: File not found for url: http://localhost:8000/users.json
INFO:root:Fetching data from API...
Traceback (most recent call last):
  File "/mnt/c/Users/manib/data_pipeline_project/pipeline.py", line 39, in <module>
    run_pipeline()
  File "/mnt/c/Users/manib/data_pipeline_project/pipeline.py", line 35, in run_pipeline
    data = fetch_data()
  File "/mnt/c/Users/manib/data_pipeline_project/pipeline.py", line 12, in fetch_data
    response.raise_for_status()
  File "/usr/lib/python3/dist-packages/requests/models.py", line 940, in raise_for_status
    raise HTTPError(http_error_msg, response=self)
requests.exceptions.HTTPError: 404 Client Error: File not found for url: http://localhost:8000/users.json
INFO:root:Fetching data from API...
Traceback (most recent call last):
  File "/mnt/c/Users/manib/data_pipeline_project/pipeline.py", line 39, in <module>
    run_pipeline()
  File "/mnt/c/Users/manib/data_pipeline_project/pipeline.py", line 35, in run_pipeline
    data = fetch_data()
  File "/mnt/c/Users/manib/data_pipeline_project/pipeline.py", line 12, in fetch_data
    response.raise_for_status()
  File "/usr/lib/python3/dist-packages/requests/models.py", line 940, in raise_for_status
    raise HTTPError(http_error_msg, response=self)
requests.exceptions.HTTPError: 404 Client Error: File not found for url: http://localhost:8000/users.json
INFO:root:Fetching data from API...
Traceback (most recent call last):
  File "/mnt/c/Users/manib/data_pipeline_project/pipeline.py", line 39, in <module>
    run_pipeline()
  File "/mnt/c/Users/manib/data_pipeline_project/pipeline.py", line 35, in run_pipeline
    data = fetch_data()
  File "/mnt/c/Users/manib/data_pipeline_project/pipeline.py", line 12, in fetch_data
    response.raise_for_status()
  File "/usr/lib/python3/dist-packages/requests/models.py", line 940, in raise_for_status
    raise HTTPError(http_error_msg, response=self)
requests.exceptions.HTTPError: 404 Client Error: File not found for url: http://localhost:8000/users.json
INFO:root:Fetching data from API...
Traceback (most recent call last):
  File "/mnt/c/Users/manib/data_pipeline_project/pipeline.py", line 39, in <module>
    run_pipeline()
  File "/mnt/c/Users/manib/data_pipeline_project/pipeline.py", line 35, in run_pipeline
    data = fetch_data()
  File "/mnt/c/Users/manib/data_pipeline_project/pipeline.py", line 12, in fetch_data
    response.raise_for_status()
  File "/usr/lib/python3/dist-packages/requests/models.py", line 940, in raise_for_status
    raise HTTPError(http_error_msg, response=self)
requests.exceptions.HTTPError: 404 Client Error: File not found for url: http://localhost:8000/users.json
INFO:root:Fetching data from API...
Traceback (most recent call last):
  File "/mnt/c/Users/manib/data_pipeline_project/pipeline.py", line 39, in <module>
    run_pipeline()
  File "/mnt/c/Users/manib/data_pipeline_project/pipeline.py", line 35, in run_pipeline
    data = fetch_data()
  File "/mnt/c/Users/manib/data_pipeline_project/pipeline.py", line 12, in fetch_data
    response.raise_for_status()
  File "/usr/lib/python3/dist-packages/requests/models.py", line 940, in raise_for_status
    raise HTTPError(http_error_msg, response=self)
requests.exceptions.HTTPError: 404 Client Error: File not found for url: http://localhost:8000/users.json
INFO:root:Fetching data from API...
Traceback (most recent call last):
  File "/mnt/c/Users/manib/data_pipeline_project/pipeline.py", line 39, in <module>
    run_pipeline()
  File "/mnt/c/Users/manib/data_pipeline_project/pipeline.py", line 35, in run_pipeline
    data = fetch_data()
  File "/mnt/c/Users/manib/data_pipeline_project/pipeline.py", line 12, in fetch_data
    response.raise_for_status()
  File "/usr/lib/python3/dist-packages/requests/models.py", line 940, in raise_for_status
    raise HTTPError(http_error_msg, response=self)
requests.exceptions.HTTPError: 404 Client Error: File not found for url: http://localhost:8000/users.json
INFO:root:Fetching data from API...
Traceback (most recent call last):
  File "/mnt/c/Users/manib/data_pipeline_project/pipeline.py", line 39, in <module>
    run_pipeline()
  File "/mnt/c/Users/manib/data_pipeline_project/pipeline.py", line 35, in run_pipeline
    data = fetch_data()
  File "/mnt/c/Users/manib/data_pipeline_project/pipeline.py", line 12, in fetch_data
    response.raise_for_status()
  File "/usr/lib/python3/dist-packages/requests/models.py", line 940, in raise_for_status
    raise HTTPError(http_error_msg, response=self)
requests.exceptions.HTTPError: 404 Client Error: File not found for url: http://localhost:8000/users.json
INFO:root:Fetching data from API...
Traceback (most recent call last):
  File "/mnt/c/Users/manib/data_pipeline_project/pipeline.py", line 39, in <module>
    run_pipeline()
  File "/mnt/c/Users/manib/data_pipeline_project/pipeline.py", line 35, in run_pipeline
    data = fetch_data()
  File "/mnt/c/Users/manib/data_pipeline_project/pipeline.py", line 12, in fetch_data
    response.raise_for_status()
  File "/usr/lib/python3/dist-packages/requests/models.py", line 940, in raise_for_status
    raise HTTPError(http_error_msg, response=self)
requests.exceptions.HTTPError: 404 Client Error: File not found for url: http://localhost:8000/users.json
INFO:root:Fetching data from API...
Traceback (most recent call last):
  File "/mnt/c/Users/manib/data_pipeline_project/pipeline.py", line 39, in <module>
    run_pipeline()
  File "/mnt/c/Users/manib/data_pipeline_project/pipeline.py", line 35, in run_pipeline
    data = fetch_data()
  File "/mnt/c/Users/manib/data_pipeline_project/pipeline.py", line 12, in fetch_data
    response.raise_for_status()
  File "/usr/lib/python3/dist-packages/requests/models.py", line 940, in raise_for_status
    raise HTTPError(http_error_msg, response=self)
requests.exceptions.HTTPError: 404 Client Error: File not found for url: http://localhost:8000/users.json
INFO:root:Fetching data from API...
Traceback (most recent call last):
  File "/mnt/c/Users/manib/data_pipeline_project/pipeline.py", line 39, in <module>
    run_pipeline()
  File "/mnt/c/Users/manib/data_pipeline_project/pipeline.py", line 35, in run_pipeline
    data = fetch_data()
  File "/mnt/c/Users/manib/data_pipeline_project/pipeline.py", line 12, in fetch_data
    response.raise_for_status()
  File "/usr/lib/python3/dist-packages/requests/models.py", line 940, in raise_for_status
    raise HTTPError(http_error_msg, response=self)
requests.exceptions.HTTPError: 404 Client Error: File not found for url: http://localhost:8000/users.json
INFO:root:Fetching data from API...
Traceback (most recent call last):
  File "/mnt/c/Users/manib/data_pipeline_project/pipeline.py", line 39, in <module>
    run_pipeline()
  File "/mnt/c/Users/manib/data_pipeline_project/pipeline.py", line 35, in run_pipeline
    data = fetch_data()
  File "/mnt/c/Users/manib/data_pipeline_project/pipeline.py", line 12, in fetch_data
    response.raise_for_status()
  File "/usr/lib/python3/dist-packages/requests/models.py", line 940, in raise_for_status
    raise HTTPError(http_error_msg, response=self)
requests.exceptions.HTTPError: 404 Client Error: File not found for url: http://localhost:8000/users.json
INFO:root:Fetching data from API...
Traceback (most recent call last):
  File "/mnt/c/Users/manib/data_pipeline_project/pipeline.py", line 39, in <module>
    run_pipeline()
  File "/mnt/c/Users/manib/data_pipeline_project/pipeline.py", line 35, in run_pipeline
    data = fetch_data()
  File "/mnt/c/Users/manib/data_pipeline_project/pipeline.py", line 12, in fetch_data
    response.raise_for_status()
  File "/usr/lib/python3/dist-packages/requests/models.py", line 940, in raise_for_status
    raise HTTPError(http_error_msg, response=self)
requests.exceptions.HTTPError: 404 Client Error: File not found for url: http://localhost:8000/users.json
INFO:root:Fetching data from API...
Traceback (most recent call last):
  File "/mnt/c/Users/manib/data_pipeline_project/pipeline.py", line 39, in <module>
    run_pipeline()
  File "/mnt/c/Users/manib/data_pipeline_project/pipeline.py", line 35, in run_pipeline
    data = fetch_data()
  File "/mnt/c/Users/manib/data_pipeline_project/pipeline.py", line 12, in fetch_data
    response.raise_for_status()
  File "/usr/lib/python3/dist-packages/requests/models.py", line 940, in raise_for_status
    raise HTTPError(http_error_msg, response=self)
requests.exceptions.HTTPError: 404 Client Error: File not found for url: http://localhost:8000/users.json
INFO:root:Fetching data from API...
Traceback (most recent call last):
  File "/mnt/c/Users/manib/data_pipeline_project/pipeline.py", line 39, in <module>
    run_pipeline()
  File "/mnt/c/Users/manib/data_pipeline_project/pipeline.py", line 35, in run_pipeline
    data = fetch_data()
  File "/mnt/c/Users/manib/data_pipeline_project/pipeline.py", line 12, in fetch_data
    response.raise_for_status()
  File "/usr/lib/python3/dist-packages/requests/models.py", line 940, in raise_for_status
    raise HTTPError(http_error_msg, response=self)
requests.exceptions.HTTPError: 404 Client Error: File not found for url: http://localhost:8000/users.json
INFO:root:Fetching data from API...
Traceback (most recent call last):
  File "/mnt/c/Users/manib/data_pipeline_project/pipeline.py", line 39, in <module>
    run_pipeline()
  File "/mnt/c/Users/manib/data_pipeline_project/pipeline.py", line 35, in run_pipeline
    data = fetch_data()
  File "/mnt/c/Users/manib/data_pipeline_project/pipeline.py", line 12, in fetch_data
    response.raise_for_status()
  File "/usr/lib/python3/dist-packages/requests/models.py", line 940, in raise_for_status
    raise HTTPError(http_error_msg, response=self)
requests.exceptions.HTTPError: 404 Client Error: File not found for url: http://localhost:8000/users.json
INFO:root:Fetching data from API...
Traceback (most recent call last):
  File "/mnt/c/Users/manib/data_pipeline_project/pipeline.py", line 39, in <module>
    run_pipeline()
  File "/mnt/c/Users/manib/data_pipeline_project/pipeline.py", line 35, in run_pipeline
    data = fetch_data()
  File "/mnt/c/Users/manib/data_pipeline_project/pipeline.py", line 12, in fetch_data
    response.raise_for_status()
  File "/usr/lib/python3/dist-packages/requests/models.py", line 940, in raise_for_status
    raise HTTPError(http_error_msg, response=self)
requests.exceptions.HTTPError: 404 Client Error: File not found for url: http://localhost:8000/users.json
INFO:root:Fetching data from API...
Traceback (most recent call last):
  File "/mnt/c/Users/manib/data_pipeline_project/pipeline.py", line 39, in <module>
    run_pipeline()
  File "/mnt/c/Users/manib/data_pipeline_project/pipeline.py", line 35, in run_pipeline
    data = fetch_data()
  File "/mnt/c/Users/manib/data_pipeline_project/pipeline.py", line 12, in fetch_data
    response.raise_for_status()
  File "/usr/lib/python3/dist-packages/requests/models.py", line 940, in raise_for_status
    raise HTTPError(http_error_msg, response=self)
requests.exceptions.HTTPError: 404 Client Error: File not found for url: http://localhost:8000/users.json
INFO:root:Fetching data from API...
Traceback (most recent call last):
  File "/mnt/c/Users/manib/data_pipeline_project/pipeline.py", line 39, in <module>
    run_pipeline()
  File "/mnt/c/Users/manib/data_pipeline_project/pipeline.py", line 35, in run_pipeline
    data = fetch_data()
  File "/mnt/c/Users/manib/data_pipeline_project/pipeline.py", line 12, in fetch_data
    response.raise_for_status()
  File "/usr/lib/python3/dist-packages/requests/models.py", line 940, in raise_for_status
    raise HTTPError(http_error_msg, response=self)
requests.exceptions.HTTPError: 404 Client Error: File not found for url: http://localhost:8000/users.json
INFO:root:Fetching data from API...
Traceback (most recent call last):
  File "/mnt/c/Users/manib/data_pipeline_project/pipeline.py", line 39, in <module>
    run_pipeline()
  File "/mnt/c/Users/manib/data_pipeline_project/pipeline.py", line 35, in run_pipeline
    data = fetch_data()
  File "/mnt/c/Users/manib/data_pipeline_project/pipeline.py", line 12, in fetch_data
    response.raise_for_status()
  File "/usr/lib/python3/dist-packages/requests/models.py", line 940, in raise_for_status
    raise HTTPError(http_error_msg, response=self)
requests.exceptions.HTTPError: 404 Client Error: File not found for url: http://localhost:8000/users.json
INFO:root:Fetching data from API...
Traceback (most recent call last):
  File "/mnt/c/Users/manib/data_pipeline_project/pipeline.py", line 39, in <module>
    run_pipeline()
  File "/mnt/c/Users/manib/data_pipeline_project/pipeline.py", line 35, in run_pipeline
    data = fetch_data()
  File "/mnt/c/Users/manib/data_pipeline_project/pipeline.py", line 12, in fetch_data
    response.raise_for_status()
  File "/usr/lib/python3/dist-packages/requests/models.py", line 940, in raise_for_status
    raise HTTPError(http_error_msg, response=self)
requests.exceptions.HTTPError: 404 Client Error: File not found for url: http://localhost:8000/users.json
INFO:root:Fetching data from API...
Traceback (most recent call last):
  File "/mnt/c/Users/manib/data_pipeline_project/pipeline.py", line 39, in <module>
    run_pipeline()
  File "/mnt/c/Users/manib/data_pipeline_project/pipeline.py", line 35, in run_pipeline
    data = fetch_data()
  File "/mnt/c/Users/manib/data_pipeline_project/pipeline.py", line 12, in fetch_data
    response.raise_for_status()
  File "/usr/lib/python3/dist-packages/requests/models.py", line 940, in raise_for_status
    raise HTTPError(http_error_msg, response=self)
requests.exceptions.HTTPError: 404 Client Error: File not found for url: http://localhost:8000/users.json
INFO:root:Fetching data from API...
Traceback (most recent call last):
  File "/mnt/c/Users/manib/data_pipeline_project/pipeline.py", line 39, in <module>
    run_pipeline()
  File "/mnt/c/Users/manib/data_pipeline_project/pipeline.py", line 35, in run_pipeline
    data = fetch_data()
  File "/mnt/c/Users/manib/data_pipeline_project/pipeline.py", line 12, in fetch_data
    response.raise_for_status()
  File "/usr/lib/python3/dist-packages/requests/models.py", line 940, in raise_for_status
    raise HTTPError(http_error_msg, response=self)
requests.exceptions.HTTPError: 404 Client Error: File not found for url: http://localhost:8000/users.json
INFO:root:Fetching data from API...
Traceback (most recent call last):
  File "/mnt/c/Users/manib/data_pipeline_project/pipeline.py", line 39, in <module>
    run_pipeline()
  File "/mnt/c/Users/manib/data_pipeline_project/pipeline.py", line 35, in run_pipeline
    data = fetch_data()
  File "/mnt/c/Users/manib/data_pipeline_project/pipeline.py", line 12, in fetch_data
    response.raise_for_status()
  File "/usr/lib/python3/dist-packages/requests/models.py", line 940, in raise_for_status
    raise HTTPError(http_error_msg, response=self)
requests.exceptions.HTTPError: 404 Client Error: File not found for url: http://localhost:8000/users.json
INFO:root:Fetching data from API...
Traceback (most recent call last):
  File "/mnt/c/Users/manib/data_pipeline_project/pipeline.py", line 39, in <module>
    run_pipeline()
  File "/mnt/c/Users/manib/data_pipeline_project/pipeline.py", line 35, in run_pipeline
    data = fetch_data()
  File "/mnt/c/Users/manib/data_pipeline_project/pipeline.py", line 12, in fetch_data
    response.raise_for_status()
  File "/usr/lib/python3/dist-packages/requests/models.py", line 940, in raise_for_status
    raise HTTPError(http_error_msg, response=self)
requests.exceptions.HTTPError: 404 Client Error: File not found for url: http://localhost:8000/users.json
INFO:root:Fetching data from API...
Traceback (most recent call last):
  File "/mnt/c/Users/manib/data_pipeline_project/pipeline.py", line 39, in <module>
    run_pipeline()
  File "/mnt/c/Users/manib/data_pipeline_project/pipeline.py", line 35, in run_pipeline
    data = fetch_data()
  File "/mnt/c/Users/manib/data_pipeline_project/pipeline.py", line 12, in fetch_data
    response.raise_for_status()
  File "/usr/lib/python3/dist-packages/requests/models.py", line 940, in raise_for_status
    raise HTTPError(http_error_msg, response=self)
requests.exceptions.HTTPError: 404 Client Error: File not found for url: http://localhost:8000/users.json
INFO:root:Fetching data from API...
Traceback (most recent call last):
  File "/mnt/c/Users/manib/data_pipeline_project/pipeline.py", line 39, in <module>
    run_pipeline()
  File "/mnt/c/Users/manib/data_pipeline_project/pipeline.py", line 35, in run_pipeline
    data = fetch_data()
  File "/mnt/c/Users/manib/data_pipeline_project/pipeline.py", line 12, in fetch_data
    response.raise_for_status()
  File "/usr/lib/python3/dist-packages/requests/models.py", line 940, in raise_for_status
    raise HTTPError(http_error_msg, response=self)
requests.exceptions.HTTPError: 404 Client Error: File not found for url: http://localhost:8000/users.json
INFO:root:Fetching data from API...
Traceback (most recent call last):
  File "/mnt/c/Users/manib/data_pipeline_project/pipeline.py", line 39, in <module>
    run_pipeline()
  File "/mnt/c/Users/manib/data_pipeline_project/pipeline.py", line 35, in run_pipeline
    data = fetch_data()
  File "/mnt/c/Users/manib/data_pipeline_project/pipeline.py", line 12, in fetch_data
    response.raise_for_status()
  File "/usr/lib/python3/dist-packages/requests/models.py", line 940, in raise_for_status
    raise HTTPError(http_error_msg, response=self)
requests.exceptions.HTTPError: 404 Client Error: File not found for url: http://localhost:8000/users.json
INFO:root:Fetching data from API...
Traceback (most recent call last):
  File "/mnt/c/Users/manib/data_pipeline_project/pipeline.py", line 39, in <module>
    run_pipeline()
  File "/mnt/c/Users/manib/data_pipeline_project/pipeline.py", line 35, in run_pipeline
    data = fetch_data()
  File "/mnt/c/Users/manib/data_pipeline_project/pipeline.py", line 12, in fetch_data
    response.raise_for_status()
  File "/usr/lib/python3/dist-packages/requests/models.py", line 940, in raise_for_status
    raise HTTPError(http_error_msg, response=self)
requests.exceptions.HTTPError: 404 Client Error: File not found for url: http://localhost:8000/users.json
INFO:root:Fetching data from API...
Traceback (most recent call last):
  File "/mnt/c/Users/manib/data_pipeline_project/pipeline.py", line 39, in <module>
    run_pipeline()
  File "/mnt/c/Users/manib/data_pipeline_project/pipeline.py", line 35, in run_pipeline
    data = fetch_data()
  File "/mnt/c/Users/manib/data_pipeline_project/pipeline.py", line 12, in fetch_data
    response.raise_for_status()
  File "/usr/lib/python3/dist-packages/requests/models.py", line 940, in raise_for_status
    raise HTTPError(http_error_msg, response=self)
requests.exceptions.HTTPError: 404 Client Error: File not found for url: http://localhost:8000/users.json
INFO:root:Fetching data from API...
Traceback (most recent call last):
  File "/mnt/c/Users/manib/data_pipeline_project/pipeline.py", line 39, in <module>
    run_pipeline()
  File "/mnt/c/Users/manib/data_pipeline_project/pipeline.py", line 35, in run_pipeline
    data = fetch_data()
  File "/mnt/c/Users/manib/data_pipeline_project/pipeline.py", line 12, in fetch_data
    response.raise_for_status()
  File "/usr/lib/python3/dist-packages/requests/models.py", line 940, in raise_for_status
    raise HTTPError(http_error_msg, response=self)
requests.exceptions.HTTPError: 404 Client Error: File not found for url: http://localhost:8000/users.json
INFO:root:Fetching data from API...
Traceback (most recent call last):
  File "/mnt/c/Users/manib/data_pipeline_project/pipeline.py", line 39, in <module>
    run_pipeline()
  File "/mnt/c/Users/manib/data_pipeline_project/pipeline.py", line 35, in run_pipeline
    data = fetch_data()
  File "/mnt/c/Users/manib/data_pipeline_project/pipeline.py", line 12, in fetch_data
    response.raise_for_status()
  File "/usr/lib/python3/dist-packages/requests/models.py", line 940, in raise_for_status
    raise HTTPError(http_error_msg, response=self)
requests.exceptions.HTTPError: 404 Client Error: File not found for url: http://localhost:8000/users.json
INFO:root:Fetching data from API...
Traceback (most recent call last):
  File "/mnt/c/Users/manib/data_pipeline_project/pipeline.py", line 39, in <module>
    run_pipeline()
  File "/mnt/c/Users/manib/data_pipeline_project/pipeline.py", line 35, in run_pipeline
    data = fetch_data()
  File "/mnt/c/Users/manib/data_pipeline_project/pipeline.py", line 12, in fetch_data
    response.raise_for_status()
  File "/usr/lib/python3/dist-packages/requests/models.py", line 940, in raise_for_status
    raise HTTPError(http_error_msg, response=self)
requests.exceptions.HTTPError: 404 Client Error: File not found for url: http://localhost:8000/users.json
INFO:root:Fetching data from API...
Traceback (most recent call last):
  File "/mnt/c/Users/manib/data_pipeline_project/pipeline.py", line 39, in <module>
    run_pipeline()
  File "/mnt/c/Users/manib/data_pipeline_project/pipeline.py", line 35, in run_pipeline
    data = fetch_data()
  File "/mnt/c/Users/manib/data_pipeline_project/pipeline.py", line 12, in fetch_data
    response.raise_for_status()
  File "/usr/lib/python3/dist-packages/requests/models.py", line 940, in raise_for_status
    raise HTTPError(http_error_msg, response=self)
requests.exceptions.HTTPError: 404 Client Error: File not found for url: http://localhost:8000/users.json
INFO:root:Fetching data from API...
Traceback (most recent call last):
  File "/mnt/c/Users/manib/data_pipeline_project/pipeline.py", line 39, in <module>
    run_pipeline()
  File "/mnt/c/Users/manib/data_pipeline_project/pipeline.py", line 35, in run_pipeline
    data = fetch_data()
  File "/mnt/c/Users/manib/data_pipeline_project/pipeline.py", line 12, in fetch_data
    response.raise_for_status()
  File "/usr/lib/python3/dist-packages/requests/models.py", line 940, in raise_for_status
    raise HTTPError(http_error_msg, response=self)
requests.exceptions.HTTPError: 404 Client Error: File not found for url: http://localhost:8000/users.json
INFO:root:Fetching data from API...
Traceback (most recent call last):
  File "/mnt/c/Users/manib/data_pipeline_project/pipeline.py", line 39, in <module>
    run_pipeline()
  File "/mnt/c/Users/manib/data_pipeline_project/pipeline.py", line 35, in run_pipeline
    data = fetch_data()
  File "/mnt/c/Users/manib/data_pipeline_project/pipeline.py", line 12, in fetch_data
    response.raise_for_status()
  File "/usr/lib/python3/dist-packages/requests/models.py", line 940, in raise_for_status
    raise HTTPError(http_error_msg, response=self)
requests.exceptions.HTTPError: 404 Client Error: File not found for url: http://localhost:8000/users.json
INFO:root:Fetching data from API...
Traceback (most recent call last):
  File "/mnt/c/Users/manib/data_pipeline_project/pipeline.py", line 39, in <module>
    run_pipeline()
  File "/mnt/c/Users/manib/data_pipeline_project/pipeline.py", line 35, in run_pipeline
    data = fetch_data()
  File "/mnt/c/Users/manib/data_pipeline_project/pipeline.py", line 12, in fetch_data
    response.raise_for_status()
  File "/usr/lib/python3/dist-packages/requests/models.py", line 940, in raise_for_status
    raise HTTPError(http_error_msg, response=self)
requests.exceptions.HTTPError: 404 Client Error: File not found for url: http://localhost:8000/users.json
INFO:root:Fetching data from API...
Traceback (most recent call last):
  File "/mnt/c/Users/manib/data_pipeline_project/pipeline.py", line 39, in <module>
    run_pipeline()
  File "/mnt/c/Users/manib/data_pipeline_project/pipeline.py", line 35, in run_pipeline
    data = fetch_data()
  File "/mnt/c/Users/manib/data_pipeline_project/pipeline.py", line 12, in fetch_data
    response.raise_for_status()
  File "/usr/lib/python3/dist-packages/requests/models.py", line 940, in raise_for_status
    raise HTTPError(http_error_msg, response=self)
requests.exceptions.HTTPError: 404 Client Error: File not found for url: http://localhost:8000/users.json
INFO:root:Fetching data from API...
Traceback (most recent call last):
  File "/mnt/c/Users/manib/data_pipeline_project/pipeline.py", line 39, in <module>
    run_pipeline()
  File "/mnt/c/Users/manib/data_pipeline_project/pipeline.py", line 35, in run_pipeline
    data = fetch_data()
  File "/mnt/c/Users/manib/data_pipeline_project/pipeline.py", line 12, in fetch_data
    response.raise_for_status()
  File "/usr/lib/python3/dist-packages/requests/models.py", line 940, in raise_for_status
    raise HTTPError(http_error_msg, response=self)
requests.exceptions.HTTPError: 404 Client Error: File not found for url: http://localhost:8000/users.json
INFO:root:Fetching data from API...
Traceback (most recent call last):
  File "/mnt/c/Users/manib/data_pipeline_project/pipeline.py", line 39, in <module>
    run_pipeline()
  File "/mnt/c/Users/manib/data_pipeline_project/pipeline.py", line 35, in run_pipeline
    data = fetch_data()
  File "/mnt/c/Users/manib/data_pipeline_project/pipeline.py", line 12, in fetch_data
    response.raise_for_status()
  File "/usr/lib/python3/dist-packages/requests/models.py", line 940, in raise_for_status
    raise HTTPError(http_error_msg, response=self)
requests.exceptions.HTTPError: 404 Client Error: File not found for url: http://localhost:8000/users.json
INFO:root:Fetching data from API...
Traceback (most recent call last):
  File "/mnt/c/Users/manib/data_pipeline_project/pipeline.py", line 39, in <module>
    run_pipeline()
  File "/mnt/c/Users/manib/data_pipeline_project/pipeline.py", line 35, in run_pipeline
    data = fetch_data()
  File "/mnt/c/Users/manib/data_pipeline_project/pipeline.py", line 12, in fetch_data
    response.raise_for_status()
  File "/usr/lib/python3/dist-packages/requests/models.py", line 940, in raise_for_status
    raise HTTPError(http_error_msg, response=self)
requests.exceptions.HTTPError: 404 Client Error: File not found for url: http://localhost:8000/users.json
INFO:root:Fetching data from API...
Traceback (most recent call last):
  File "/mnt/c/Users/manib/data_pipeline_project/pipeline.py", line 39, in <module>
    run_pipeline()
  File "/mnt/c/Users/manib/data_pipeline_project/pipeline.py", line 35, in run_pipeline
    data = fetch_data()
  File "/mnt/c/Users/manib/data_pipeline_project/pipeline.py", line 12, in fetch_data
    response.raise_for_status()
  File "/usr/lib/python3/dist-packages/requests/models.py", line 940, in raise_for_status
    raise HTTPError(http_error_msg, response=self)
requests.exceptions.HTTPError: 404 Client Error: File not found for url: http://localhost:8000/users.json
INFO:root:Fetching data from API...
Traceback (most recent call last):
  File "/mnt/c/Users/manib/data_pipeline_project/pipeline.py", line 39, in <module>
    run_pipeline()
  File "/mnt/c/Users/manib/data_pipeline_project/pipeline.py", line 35, in run_pipeline
    data = fetch_data()
  File "/mnt/c/Users/manib/data_pipeline_project/pipeline.py", line 12, in fetch_data
    response.raise_for_status()
  File "/usr/lib/python3/dist-packages/requests/models.py", line 940, in raise_for_status
    raise HTTPError(http_error_msg, response=self)
requests.exceptions.HTTPError: 404 Client Error: File not found for url: http://localhost:8000/users.json
INFO:root:Fetching data from API...
Traceback (most recent call last):
  File "/mnt/c/Users/manib/data_pipeline_project/pipeline.py", line 39, in <module>
    run_pipeline()
  File "/mnt/c/Users/manib/data_pipeline_project/pipeline.py", line 35, in run_pipeline
    data = fetch_data()
  File "/mnt/c/Users/manib/data_pipeline_project/pipeline.py", line 12, in fetch_data
    response.raise_for_status()
  File "/usr/lib/python3/dist-packages/requests/models.py", line 940, in raise_for_status
    raise HTTPError(http_error_msg, response=self)
requests.exceptions.HTTPError: 404 Client Error: File not found for url: http://localhost:8000/users.json
INFO:root:Fetching data from API...
Traceback (most recent call last):
  File "/mnt/c/Users/manib/data_pipeline_project/pipeline.py", line 39, in <module>
    run_pipeline()
  File "/mnt/c/Users/manib/data_pipeline_project/pipeline.py", line 35, in run_pipeline
    data = fetch_data()
  File "/mnt/c/Users/manib/data_pipeline_project/pipeline.py", line 12, in fetch_data
    response.raise_for_status()
  File "/usr/lib/python3/dist-packages/requests/models.py", line 940, in raise_for_status
    raise HTTPError(http_error_msg, response=self)
requests.exceptions.HTTPError: 404 Client Error: File not found for url: http://localhost:8000/users.json
INFO:root:Fetching data from API...
Traceback (most recent call last):
  File "/mnt/c/Users/manib/data_pipeline_project/pipeline.py", line 39, in <module>
    run_pipeline()
  File "/mnt/c/Users/manib/data_pipeline_project/pipeline.py", line 35, in run_pipeline
    data = fetch_data()
  File "/mnt/c/Users/manib/data_pipeline_project/pipeline.py", line 12, in fetch_data
    response.raise_for_status()
  File "/usr/lib/python3/dist-packages/requests/models.py", line 940, in raise_for_status
    raise HTTPError(http_error_msg, response=self)
requests.exceptions.HTTPError: 404 Client Error: File not found for url: http://localhost:8000/users.json
INFO:root:Fetching data from API...
Traceback (most recent call last):
  File "/mnt/c/Users/manib/data_pipeline_project/pipeline.py", line 39, in <module>
    run_pipeline()
  File "/mnt/c/Users/manib/data_pipeline_project/pipeline.py", line 35, in run_pipeline
    data = fetch_data()
  File "/mnt/c/Users/manib/data_pipeline_project/pipeline.py", line 12, in fetch_data
    response.raise_for_status()
  File "/usr/lib/python3/dist-packages/requests/models.py", line 940, in raise_for_status
    raise HTTPError(http_error_msg, response=self)
requests.exceptions.HTTPError: 404 Client Error: File not found for url: http://localhost:8000/users.json
INFO:root:Fetching data from API...
Traceback (most recent call last):
  File "/mnt/c/Users/manib/data_pipeline_project/pipeline.py", line 39, in <module>
    run_pipeline()
  File "/mnt/c/Users/manib/data_pipeline_project/pipeline.py", line 35, in run_pipeline
    data = fetch_data()
  File "/mnt/c/Users/manib/data_pipeline_project/pipeline.py", line 12, in fetch_data
    response.raise_for_status()
  File "/usr/lib/python3/dist-packages/requests/models.py", line 940, in raise_for_status
    raise HTTPError(http_error_msg, response=self)
requests.exceptions.HTTPError: 404 Client Error: File not found for url: http://localhost:8000/users.json
INFO:root:Fetching data from API...
Traceback (most recent call last):
  File "/mnt/c/Users/manib/data_pipeline_project/pipeline.py", line 39, in <module>
    run_pipeline()
  File "/mnt/c/Users/manib/data_pipeline_project/pipeline.py", line 35, in run_pipeline
    data = fetch_data()
  File "/mnt/c/Users/manib/data_pipeline_project/pipeline.py", line 12, in fetch_data
    response.raise_for_status()
  File "/usr/lib/python3/dist-packages/requests/models.py", line 940, in raise_for_status
    raise HTTPError(http_error_msg, response=self)
requests.exceptions.HTTPError: 404 Client Error: File not found for url: http://localhost:8000/users.json
INFO:root:Fetching data from API...
Traceback (most recent call last):
  File "/mnt/c/Users/manib/data_pipeline_project/pipeline.py", line 39, in <module>
    run_pipeline()
  File "/mnt/c/Users/manib/data_pipeline_project/pipeline.py", line 35, in run_pipeline
    data = fetch_data()
  File "/mnt/c/Users/manib/data_pipeline_project/pipeline.py", line 12, in fetch_data
    response.raise_for_status()
  File "/usr/lib/python3/dist-packages/requests/models.py", line 940, in raise_for_status
    raise HTTPError(http_error_msg, response=self)
requests.exceptions.HTTPError: 404 Client Error: File not found for url: http://localhost:8000/users.json
INFO:root:Fetching data from API...
Traceback (most recent call last):
  File "/mnt/c/Users/manib/data_pipeline_project/pipeline.py", line 39, in <module>
    run_pipeline()
  File "/mnt/c/Users/manib/data_pipeline_project/pipeline.py", line 35, in run_pipeline
    data = fetch_data()
  File "/mnt/c/Users/manib/data_pipeline_project/pipeline.py", line 12, in fetch_data
    response.raise_for_status()
  File "/usr/lib/python3/dist-packages/requests/models.py", line 940, in raise_for_status
    raise HTTPError(http_error_msg, response=self)
requests.exceptions.HTTPError: 404 Client Error: File not found for url: http://localhost:8000/users.json
INFO:root:Fetching data from API...
Traceback (most recent call last):
  File "/mnt/c/Users/manib/data_pipeline_project/pipeline.py", line 39, in <module>
    run_pipeline()
  File "/mnt/c/Users/manib/data_pipeline_project/pipeline.py", line 35, in run_pipeline
    data = fetch_data()
  File "/mnt/c/Users/manib/data_pipeline_project/pipeline.py", line 12, in fetch_data
    response.raise_for_status()
  File "/usr/lib/python3/dist-packages/requests/models.py", line 940, in raise_for_status
    raise HTTPError(http_error_msg, response=self)
requests.exceptions.HTTPError: 404 Client Error: File not found for url: http://localhost:8000/users.json
INFO:root:Fetching data from API...
Traceback (most recent call last):
  File "/mnt/c/Users/manib/data_pipeline_project/pipeline.py", line 39, in <module>
    run_pipeline()
  File "/mnt/c/Users/manib/data_pipeline_project/pipeline.py", line 35, in run_pipeline
    data = fetch_data()
  File "/mnt/c/Users/manib/data_pipeline_project/pipeline.py", line 12, in fetch_data
    response.raise_for_status()
  File "/usr/lib/python3/dist-packages/requests/models.py", line 940, in raise_for_status
    raise HTTPError(http_error_msg, response=self)
requests.exceptions.HTTPError: 404 Client Error: File not found for url: http://localhost:8000/users.json
INFO:root:Fetching data from API...
Traceback (most recent call last):
  File "/mnt/c/Users/manib/data_pipeline_project/pipeline.py", line 39, in <module>
    run_pipeline()
  File "/mnt/c/Users/manib/data_pipeline_project/pipeline.py", line 35, in run_pipeline
    data = fetch_data()
  File "/mnt/c/Users/manib/data_pipeline_project/pipeline.py", line 12, in fetch_data
    response.raise_for_status()
  File "/usr/lib/python3/dist-packages/requests/models.py", line 940, in raise_for_status
    raise HTTPError(http_error_msg, response=self)
requests.exceptions.HTTPError: 404 Client Error: File not found for url: http://localhost:8000/users.json
INFO:root:Fetching data from API...
Traceback (most recent call last):
  File "/mnt/c/Users/manib/data_pipeline_project/pipeline.py", line 39, in <module>
    run_pipeline()
  File "/mnt/c/Users/manib/data_pipeline_project/pipeline.py", line 35, in run_pipeline
    data = fetch_data()
  File "/mnt/c/Users/manib/data_pipeline_project/pipeline.py", line 12, in fetch_data
    response.raise_for_status()
  File "/usr/lib/python3/dist-packages/requests/models.py", line 940, in raise_for_status
    raise HTTPError(http_error_msg, response=self)
requests.exceptions.HTTPError: 404 Client Error: File not found for url: http://localhost:8000/users.json
